Workbook

Sheet SL_PH
A1: NORKLE DATA | B1: REFERENCE ONLY
A3: targetData.version | B3: targetData.prodFmly1 | C3: targetData.prodFmly2 | D3: targetData.prodFmly3 | E3: targetData.segmentCode | F3: targetData.Cell_Name | G3: Subject Line | H3: Preheader | I3: Banner 1 Name | J3: Banner 1 - Image Path | K3: Banner 1 - Headline Copy | L3: Banner 1 - Subhead Copy | M3: Banner 1 - Subcopy | N3: Banner 1 - CTA Copy | O3: Banner 1 - CTA Link | P3: Banner 1 - CTA Deeplink | Q3: Banner 1 - CTA 2 Link | R3: Banner 1 - CTA 2 Deeplink | S3: Banner 2 Name | T3: Banner 2 - Image Path | U3: Banner 2 - Headline Copy | V3: Banner 2 - Subhead Copy | W3: Banner 2 - Subcopy | X3: Banner 2 - CTA Copy | Y3: Banner 2 - CTA Link | Z3: Banner 2 - CTA Deeplink | AA3: Banner 2 - CTA 2Copy | AB3: Banner 2 - CTA 2 Link | AC3: Banner 2 - CTA 2 Deeplink | AD3: Banner 3 Name | AE3: Banner 3 - Image Path | AF3: Banner 3 - Headline Copy | AG3: Banner 3 - Subhead Copy | AH3: Banner 3 - Subcopy | AI3: Banner 3 - CTA Copy | AJ3: Banner 3 - CTA Link | AK3: Banner 3 - CTA Deeplink | AL3: Banner 3 - CTA 2 Copy | AM3: Banner 3 - CTA 2 Link | AN3: Banner 3 - CTA 2 Deeplink | AO3: Banner 4 Name | AP3: Banner 4 - Image Path | AQ3: Banner 4 - Headline Copy | AR3: Banner 4 - Subhead Copy | AS3: Banner 4 - Subcopy | AT3: Banner 4 - CTA Copy | AU3: Banner 4 - CTA Link | AV3: Banner 4 - CTA Deeplink | AW3: Banner 4 - CTA 2 Copy | AX3: Banner 4 - CTA 2 Link | AY3: Banner 4 - CTA 2 Deeplink | AZ3: Banner 5 Name | BA3: Banner 5 - Image Path | BB3: Banner 5 - Headline Copy | BC3: Banner 5 - Subhead Copy | BD3: Banner 5 - Subcopy | BE3: Banner 5 - CTA Copy | BF3: Banner 5 - CTA Link | BG3: Banner 5 - CTA Deeplink | BH3: Banner 5 - CTA 2 Copy | BI3: Banner 5 - CTA 2 Link | BJ3: Banner 5- CTA 2 Deeplink | BK3: Banner 6 Name | BL3: Banner 6 - Image Path | BM3: Banner 6 - Headline Copy | BN3: Banner 6 - Subhead Copy | BO3: Banner 6 - Subcopy | BP3: Banner 6 - CTA Copy | BQ3: Banner 6 - CTA Link | BR3: Banner 6 - CTA Deeplink | BS3: Banner 6 - CTA 2 Copy | BT3: Banner 6 - CTA 2 Link | BU3: Banner 6 - CTA 2 Deeplink | BV3: Banner 7 Name | BW3: Banner 7 - Image Path | BX3: Banner 7 - Headline Copy | BY3: Banner 7 - Subhead Copy | BZ3: Banner 7 - Subcopy | CA3: Banner 7 - CTA Copy | CB3: Banner 7 - CTA Link | CC3: Banner 7 - CTA Deeplink | CD3: Banner 7 - CTA 2 Copy | CE3: Banner 7 - CTA 2 Link | CF3: Banner 7 - CTA 2 Deeplink | CG3: Banner 8 Name | CH3: Banner 8 - Image Path | CI3: Banner 8 - Headline Copy | CJ3: Banner 8 - Subhead Copy | CK3: Banner 8 - Subcopy | CL3: Banner 8 - CTA Copy | CM3: Banner 8 - CTA Link | CN3: Banner 8 - CTA Deeplink | CO3: Banner 8 - CTA 2 Copy | CP3: Banner 8 - CTA 2 Link | CQ3: Banner 8 - CTA 2 Deeplink | CR3: Banner 9 Name | CS3: Banner 9 - Image Path | CT3: Banner 9 - Headline Copy | CU3: Banner 9 - Subhead Copy | CV3: Banner 9 - Subcopy | CW3: Banner 9 - CTA Copy | CX3: Banner 9 - CTA Link | CY3: Banner 9 - CTA Deeplink | CZ3: Banner 9 - CTA 2 Copy | DA3: Banner 9 - CTA 2 Link | DB3: Banner 9 - CTA 2 Deeplink | DC3: Banner 10 Name | DD3: Banner 10 - Image Path | DE3: Banner 10 - Headline Copy | DF3: Banner 10 - Subhead Copy | DG3: Banner 10 - Subcopy | DH3: Banner 10 - CTA Copy | DI3: Banner 10 - CTA Link | DJ3: Banner 10 - CTA Deeplink | DK3: Banner 10 - CTA 2 Copy | DL3: Banner 10 - CTA 2 Link | DM3: Banner 10 - CTA 2 Deeplink | DN3: Banner 11 Name | DO3: Banner 11 - Image Path | DP3: Banner 11 - Headline Copy | DQ3: Banner 11 - Subhead Copy | DR3: Banner 11 - Subcopy | DS3: Banner 11 - CTA Copy | DT3: Banner 11 - CTA Link | DU3: Banner 11 - CTA Deeplink | DV3: Banner 11 - CTA 2 Copy | DW3: Banner 11 - CTA 2 Link | DX3: Banner 11 - CTA 2 Deeplink | DY3: Banner 12 Name | DZ3: Banner 12 - Image Path | EA3: Banner 12 - Headline Copy | EB3: Banner 12 - Subhead Copy | EC3: Banner 12 - Subcopy | ED3: Banner 12 - CTA Copy | EE3: Banner 12 - CTA Link | EF3: Banner 12 - CTA Deeplink | EG3: Banner 12 - CTA 2 Copy | EH3: Banner 12 - CTA 2 Link | EI3: Banner 12 - CTA 2 Deeplink | EJ3: Banner 13 Name | EK3: Banner 13 - Image Path | EL3: Banner 13 - Headline Copy | EM3: Banner 13 - Subhead Copy | EN3: Banner 13 - Subcopy | EO3: Banner 13 - CTA Copy | EP3: Banner 13 - CTA Link | EQ3: Banner 13 - CTA Deeplink | ER3: Banner 13 - CTA 2 Copy | ES3: Banner 13 - CTA 2 Link | ET3: Banner 13 - CTA 2 Deeplink | EU3: Banner 14 Name | EV3: Banner 14 - Image Path | EW3: Banner 14 - Headline Copy | EX3: Banner 14 - Subhead Copy | EY3: Banner 14 - Subcopy | EZ3: Banner 14 - CTA Copy | FA3: Banner 14 - CTA Link | FB3: Banner 14 - CTA Deeplink | FC3: Banner 14 - CTA 2 Copy | FD3: Banner 14 - CTA 2 Link | FE3: Banner 14 - CTA 2 Deeplink | FF3: Banner 15 Name | FG3: Banner 15 - Image Path | FH3: Banner 15 - Headline Copy | FI3: Banner 15 - Subhead Copy | FJ3: Banner 15 - Subcopy | FK3: Banner 15 - CTA Copy | FL3: Banner 15 - CTA Link | FM3: Banner 15 - CTA Deeplink | FN3: Banner 15 - CTA 2 Copy | FO3: Banner 15 - CTA 2 Link | FP3: Banner 15 - CTA 2 Deeplink
A4: DD | B4: MB_GALAXY MB_FOLD MB_NOTE MB_MID | C4: X | D4: X | E4: Reserver EPP_Reservers | G4: Cyber Monday is on. | H4: Act fast to save on showstopping gifts while supplies last. | I4: EPP Banner | J4: NULL | K4: NULL | L4: NULL | M4: NULL | N4: NULL | O4: NULL | P4: NULL | Q4: NULL | R4: NULL | S4: Hero & Countdown Timer Image | T4: ='Dynamic Banners'!$L$4 -> Cyber-monday-1.png | U4: ='Dynamic Banners'!$M$4 -> The clock is ticking away for Cyber Monday | V4: NULL | W4: ='Dynamic Banners'!$N$4 -> Shop amazing offers on showstopping products while supplies last. | X4: NULL | Y4: =[1]MiscBanners!$B$4 -> https://www.samsung.com/us/shop/all-deals/ | Z4: =[1]MiscBanners!$C$4 -> https://shopsamsung.page.link?link=https%3A%2F%2Fwww.samsung.com%2Fus%2Fshop%2Fall-deals%2F%3FofferCID%3DearlyAccess%26utm_source%3Dsamsung%26utm_medium%3Demail%26utm_campaign%3Dholiday_deals_t3_11172020%26marsLinkCategory%3D__MARSTRACKING__%26MKM_RID%3D__BPNUMBER__%26MKM_MID%3D__DELIVERNAME__%26cid%3D__CID____SEGMENTCODE__%26bpid%3D__BPNUMBER__%26iosparam%3Dsamsungestore%25253A%25252F%25252Fgototab%252523tab%25253D4%252523offerCID%25253DearlyAccess%252523utm_source%25253Dsamsung%252523utm_medium%25253Demail%252523utm_campaign%25253Dholiday_deals_t3_11172020%252523marsLinkCategory%25253D__MARSTRACKING__%252523MKM_RID%25253D__BPNUMBER__%252523MKM_MID%25253D__DELIVERNAME__%252523cid%25253D__CID____SEGMENTCODE__%252523bpid%25253D__BPNUMBER__&utm_source=samsung&utm_medium=email&utm_campaign=holiday_deals_t3_11172020&marsLinkCategory=__MARSTRACKING__&MKM_RID=__BPNUMBER__&MKM_MID=__DELIVERNAME__&cid=__CID____SEGMENTCODE__&bpid=__BPNUMBER__&apn=com.samsung.ecomm&al=samsungestore%3A%2F%2Fgototab%23tab%3D4%23offerCID%3DearlyAccess%23utm_source%3Dsamsung%23utm_medium%3Demail%23utm_campaign%3Dholiday_deals_t3_11172020%23marsLinkCategory%3D__MARSTRACKING__%23MKM_RID%3D__BPNUMBER__%23MKM_MID%3D__DELIVERNAME__%23cid%3D__CID____SEGMENTCODE__%23bpid%3D__BPNUMBER__&afl=https%3A%2F%2Fwww.samsung.com%2Fus%2Fshop%2Fall-deals%2F%3FofferCID%3DearlyAccess%26utm_source%3Dsamsung%26utm_medium%3Demail%26utm_campaign%3Dholiday_deals_t3_11172020%26marsLinkCategory%3D__MARSTRACKING__%26MKM_RID%3D__BPNUMBER__%26MKM_MID%3D__DELIVERNAME__%26cid%3D__CID____SEGMENTCODE__%26bpid%3D__BPNUMBER__&isi=1274679179&ibi=com.samsung.ShopSamsung&ius=samsungestore&ifl=https%3A%2F%2Fwww.samsung.com%2Fus%2Fshop%2Fall-deals%2F%3FofferCID%3DearlyAccess%26utm_source%3Dsamsung%26utm_medium%3Demail%26utm_campaign%3Dholiday_deals_t3_11172020%26marsLinkCategory%3D__MARSTRACKING__%26MKM_RID%3D__BPNUMBER__%26MKM_MID%3D__DELIVERNAME__%26cid%3D__CID____SEGMENTCODE__%26bpid%3D__BPNUMBER__&efr=1 | AA4: NULL | AB4: NULL | AC4: NULL | AD4: Hero & Countdown Timer Copy | AE4: NULL | AF4: NULL | AG4: While supplies last. | AH4: Today is your day to shop some of our greatest offers of the year. Plus, enjoy $30 or more instant credit§†, in addition to your exclusive $20 instant credit, with any smartphone purchase.‡ | AI4: NULL | AJ4: =[1]MiscBanners!$B$4 -> https://www.samsung.com/us/shop/all-deals/ | AK4: =[1]MiscBanners!$C$4 -> https://shopsamsung.page.link?link=https%3A%2F%2Fwww.samsung.com%2Fus%2Fshop%2Fall-deals%2F%3FofferCID%3DearlyAccess%26utm_source%3Dsamsung%26utm_medium%3Demail%26utm_campaign%3Dholiday_deals_t3_11172020%26marsLinkCategory%3D__MARSTRACKING__%26MKM_RID%3D__BPNUMBER__%26MKM_MID%3D__DELIVERNAME__%26cid%3D__CID____SEGMENTCODE__%26bpid%3D__BPNUMBER__%26iosparam%3Dsamsungestore%25253A%25252F%25252Fgototab%252523tab%25253D4%252523offerCID%25253DearlyAccess%252523utm_source%25253Dsamsung%252523utm_medium%25253Demail%252523utm_campaign%25253Dholiday_deals_t3_11172020%252523marsLinkCategory%25253D__MARSTRACKING__%252523MKM_RID%25253D__BPNUMBER__%252523MKM_MID%25253D__DELIVERNAME__%252523cid%25253D__CID____SEGMENTCODE__%252523bpid%25253D__BPNUMBER__&utm_source=samsung&utm_medium=email&utm_campaign=holiday_deals_t3_11172020&marsLinkCategory=__MARSTRACKING__&MKM_RID=__BPNUMBER__&MKM_MID=__DELIVERNAME__&cid=__CID____SEGMENTCODE__&bpid=__BPNUMBER__&apn=com.samsung.ecomm&al=samsungestore%3A%2F%2Fgototab%23tab%3D4%23offerCID%3DearlyAccess%23utm_source%3Dsamsung%23utm_medium%3Demail%23utm_campaign%3Dholiday_deals_t3_11172020%23marsLinkCategory%3D__MARSTRACKING__%23MKM_RID%3D__BPNUMBER__%23MKM_MID%3D__DELIVERNAME__%23cid%3D__CID____SEGMENTCODE__%23bpid%3D__BPNUMBER__&afl=https%3A%2F%2Fwww.samsung.com%2Fus%2Fshop%2Fall-deals%2F%3FofferCID%3DearlyAccess%26utm_source%3Dsamsung%26utm_medium%3Demail%26utm_campaign%3Dholiday_deals_t3_11172020%26marsLinkCategory%3D__MARSTRACKING__%26MKM_RID%3D__BPNUMBER__%26MKM_MID%3D__DELIVERNAME__%26cid%3D__CID____SEGMENTCODE__%26bpid%3D__BPNUMBER__&isi=1274679179&ibi=com.samsung.ShopSamsung&ius=samsungestore&ifl=https%3A%2F%2Fwww.samsung.com%2Fus%2Fshop%2Fall-deals%2F%3FofferCID%3DearlyAccess%26utm_source%3Dsamsung%26utm_medium%3Demail%26utm_campaign%3Dholiday_deals_t3_11172020%26marsLinkCategory%3D__MARSTRACKING__%26MKM_RID%3D__BPNUMBER__%26MKM_MID%3D__DELIVERNAME__%26cid%3D__CID____SEGMENTCODE__%26bpid%3D__BPNUMBER__&efr=1 | AL4: NULL | AM4: NULL | AN4: NULL | AO4: N20F (N20/N20U) | AP4: =DDOfferCopy!E4 -> 22_IM_HeadImage_MB_Note-500xV.jpg | AQ4: =DDOfferCopy!F4 -> Get up to 70% off Galaxy Note 20 5G or Note 20 Ultra 5G | AR4: =DDOfferCopy!G4 -> Now from only $8.34/mo for 36 mos⊕ or $299.99 with eligible trade-in.ᶿ | AS4: =DDOfferCopy!H4 -> Get $150 off instantly and up to $550 trade-in credit.ᶿ | AT4: =DDOfferCopy!I4 -> Buy now | AU4: =DDOfferCopy!J4 -> https://www.samsung.com/us/smartphones/galaxy-note20-5g/buy/ | AV4: =DDOfferCopy!K4 -> https://shopsamsung.page.link?link=https%3A%2F%2Fwww.samsung.com%2Fus%2Fsmartphones%2Fgalaxy-note20-5g%2Fbuy%2F%3FofferCID%3DearlyAccess%26utm_source%3Dsamsung%26utm_medium%3Demail%26utm_campaign%3Dholiday_deals_t3_11172020%26marsLinkCategory%3D__MARSTRACKING__%26MKM_RID%3D__BPNUMBER__%26MKM_MID%3D__DELIVERNAME__%26cid%3D__CID____SEGMENTCODE__%26bpid%3D__BPNUMBER__&utm_source=samsung&utm_medium=email&utm_campaign=holiday_deals_t3_11172020&marsLinkCategory=__MARSTRACKING__&MKM_RID=__BPNUMBER__&MKM_MID=__DELIVERNAME__&cid=__CID____SEGMENTCODE__&bpid=__BPNUMBER__&apn=com.samsung.ecomm&al=samsungestore%3A%2F%2Fopenwebview%23url%3Dhttps%3A%2F%2Fwww.samsung.com%2Fus%2Fbuy%2Fsmartphones%2Fgalaxy-note20-5g%2Findex.html%3FofferCID%3DearlyAccess%26segmentName%3DholidayReserve%23utm_source%3Dsamsung%23utm_medium%3Demail%23utm_campaign%3Dholiday_deals_t3_11172020%23marsLinkCategory%3D__MARSTRACKING__%23MKM_RID%3D__BPNUMBER__%23MKM_MID%3D__DELIVERNAME__%23cid%3D__CID____SEGMENTCODE__%23bpid%3D__BPNUMBER__&afl=https%3A%2F%2Fwww.samsung.com%2Fus%2Fsmartphones%2Fgalaxy-note20-5g%2Fbuy%2F%3FofferCID%3DearlyAccess%26utm_source%3Dsamsung%26utm_medium%3Demail%26utm_campaign%3Dholiday_deals_t3_11172020%26marsLinkCategory%3D__MARSTRACKING__%26MKM_RID%3D__BPNUMBER__%26MKM_MID%3D__DELIVERNAME__%26cid%3D__CID____SEGMENTCODE__%26bpid%3D__BPNUMBER__&efr=1 | AW4: =DDOfferCopy!L4 -> NULL | ... AY4: =DDOfferCopy!N4 -> NULL | AZ4: S20 Family (S20+, S20U, S20, S20FE) | BA4: =DDOfferCopy!E5 -> 21_IM_HeadImage_MB_Galaxy-500xV.jpg | BB4: =DDOfferCopy!F5 -> Get up to 73% off Galaxy S20 5G series devices | BC4: =DDOfferCopy!G5 -> Now from only $7.92/mo for 24 mos⊕ or $189.99 with eligible trade-in.ᶿ | BD4: =DDOfferCopy!H5 -> Get up to $150 off instantly and up to $460 trade-in credit.ᶿ | BE4: =DDOfferCopy!I5 -> Buy now | BF4: =DDOfferCopy!J5 -> https://www.samsung.com/us/mobile/galaxy-s20-5g/buy/ | BG4: =DDOfferCopy!K5 -> https://shopsamsung.page.link?link=https%3A%2F%2Fwww.samsung.com%2Fus%2Fmobile%2Fgalaxy-s20-5g%2Fbuy%2F%3FofferCID%3DearlyAccess%26utm_source%3Dsamsung%26utm_medium%3Demail%26utm_campaign%3Dholiday_deals_t3_11172020%26marsLinkCategory%3D__MARSTRACKING__%26MKM_RID%3D__BPNUMBER__%26MKM_MID%3D__DELIVERNAME__%26cid%3D__CID____SEGMENTCODE__%26bpid%3D__BPNUMBER__&utm_source=samsung&utm_medium=email&utm_campaign=holiday_deals_t3_11172020&marsLinkCategory=__MARSTRACKING__&MKM_RID=__BPNUMBER__&MKM_MID=__DELIVERNAME__&cid=__CID____SEGMENTCODE__&bpid=__BPNUMBER__&apn=com.samsung.ecomm&al=samsungestore%3A%2F%2Fopenwebview%23url%3Dhttps%3A%2F%2Fwww.samsung.com%2Fus%2Fbuy%2Fsmartphones%2Fgalaxy-s20-5g%2Findex.html%3FofferCID%3DearlyAccess%26segmentName%3DholidayReserve%23utm_source%3Dsamsung%23utm_medium%3Demail%23utm_campaign%3Dholiday_deals_t3_11172020%23marsLinkCategory%3D__MARSTRACKING__%23MKM_RID%3D__BPNUMBER__%23MKM_MID%3D__DELIVERNAME__%23cid%3D__CID____SEGMENTCODE__%23bpid%3D__BPNUMBER__&afl=https%3A%2F%2Fwww.samsung.com%2Fus%2Fmobile%2Fgalaxy-s20-5g%2Fbuy%2F%3FofferCID%3DearlyAccess%26utm_source%3Dsamsung%26utm_medium%3Demail%26utm_campaign%3Dholiday_deals_t3_11172020%26marsLinkCategory%3D__MARSTRACKING__%26MKM_RID%3D__BPNUMBER__%26MKM_MID%3D__DELIVERNAME__%26cid%3D__CID____SEGMENTCODE__%26bpid%3D__BPNUMBER__&efr=1 | BH4: =DDOfferCopy!L5 -> NULL | ... BJ4: =DDOfferCopy!N5 -> NULL | BK4: Fold2 | BL4: =DDOfferCopy!E6 -> 23_IM_HeadImage_MB_Fold-500xV.jpg | BM4: =DDOfferCopy!F6 -> Get up to 50% off Galaxy Z Fold2 5G | BN4: =DDOfferCopy!G6 -> Now from only $20.84/mo for 48 mos⊕ or $999.99 with eligible trade-in.ᶿ | BO4: =DDOfferCopy!H6 -> Our best Galaxy Z Fold2 5G offer of the year. Get up to $1000 trade-in credit.ᶿ Plus, get up to $120 instant credit toward accessories.§‡ | BP4: =DDOfferCopy!I6 -> Buy now | BQ4: =DDOfferCopy!J6 -> https://www.samsung.com/us/smartphones/galaxy-z-fold2-5g/buy/ | BR4: =DDOfferCopy!K6 -> https://shopsamsung.page.link?link=https%3A%2F%2Fwww.samsung.com%2Fus%2Fsmartphones%2Fgalaxy-z-fold2-5g%2Fbuy%2F%3FofferCID%3DearlyAccess%26utm_source%3Dsamsung%26utm_medium%3Demail%26utm_campaign%3Dholiday_deals_t3_11172020%26marsLinkCategory%3D__MARSTRACKING__%26MKM_RID%3D__BPNUMBER__%26MKM_MID%3D__DELIVERNAME__%26cid%3D__CID____SEGMENTCODE__%26bpid%3D__BPNUMBER__&utm_source=samsung&utm_medium=email&utm_campaign=holiday_deals_t3_11172020&marsLinkCategory=__MARSTRACKING__&MKM_RID=__BPNUMBER__&MKM_MID=__DELIVERNAME__&cid=__CID____SEGMENTCODE__&bpid=__BPNUMBER__&apn=com.samsung.ecomm&al=samsungestore%3A%2F%2Fopenwebview%23url%3Dhttps%3A%2F%2Fwww.samsung.com%2Fus%2Fbuy%2Fsmartphones%2Fgalaxy-z-fold2-5g%2Findex.html%3FofferCID%3DearlyAccess%26segmentName%3DholidayReserve%23utm_source%3Dsamsung%23utm_medium%3Demail%23utm_campaign%3Dholiday_deals_t3_11172020%23marsLinkCategory%3D__MARSTRACKING__%23MKM_RID%3D__BPNUMBER__%23MKM_MID%3D__DELIVERNAME__%23cid%3D__CID____SEGMENTCODE__%23bpid%3D__BPNUMBER__&afl=https%3A%2F%2Fwww.samsung.com%2Fus%2Fsmartphones%2Fgalaxy-z-fold2-5g%2Fbuy%2F%3FofferCID%3DearlyAccess%26utm_source%3Dsamsung%26utm_medium%3Demail%26utm_campaign%3Dholiday_deals_t3_11172020%26marsLinkCategory%3D__MARSTRACKING__%26MKM_RID%3D__BPNUMBER__%26MKM_MID%3D__DELIVERNAME__%26cid%3D__CID____SEGMENTCODE__%26bpid%3D__BPNUMBER__&efr=1 | BS4: =DDOfferCopy!L6 -> NULL | ... BU4: =DDOfferCopy!N6 -> NULL | BV4: A71 5G / A51 5G | BW4: =DDOfferCopy!E7 -> 24-IM-A71-A51-HeadImage-500xV.jpg | BX4: =DDOfferCopy!F7 -> Get 50% off Galaxy A71 5G with T-Mobile and Verizon | BY4: =DDOfferCopy!G7 -> Now from only only $8.34/mo for 36 mos⊕ or $299.99 with eligible trade-in.ᶿ | BZ4: =DDOfferCopy!H7 -> Save up to $250 instantly and get $75 or more trade-in credit. Treat yourself to blazing fast 5G speeds and incredible features at an amazing value. | CA4: =DDOfferCopy!I7 -> Buy now | CB4: =DDOfferCopy!J7 -> https://www.samsung.com/us/mobile/phones/galaxy-a/buy/?link=galaxy-a71-5g | CC4: =DDOfferCopy!K7 -> https://shopsamsung.page.link?link=https%3A%2F%2Fwww.samsung.com%2Fus%2Fmobile%2Fphones%2Fgalaxy-a%2Fbuy%2F%3Flink%3Dgalaxy-a71-5g%26offerCID%3DearlyAccess%26utm_source%3Dsamsung%26utm_medium%3Demail%26utm_campaign%3Dholiday_deals_t3_11172020%26marsLinkCategory%3D__MARSTRACKING__%26MKM_RID%3D__BPNUMBER__%26MKM_MID%3D__DELIVERNAME__%26cid%3D__CID____SEGMENTCODE__%26bpid%3D__BPNUMBER__&utm_source=samsung&utm_medium=email&utm_campaign=holiday_deals_t3_11172020&marsLinkCategory=__MARSTRACKING__&MKM_RID=__BPNUMBER__&MKM_MID=__DELIVERNAME__&cid=__CID____SEGMENTCODE__&bpid=__BPNUMBER__&apn=com.samsung.ecomm&al=samsungestore%3A%2F%2Fopenwebview%23url%3Dhttps%3A%2F%2Fwww.samsung.com%2Fus%2Fbuy%2Fsmartphones%2Fgalaxy-a50%2Findex.html%3Flink%3Dgalaxy-a71-5g%26offerCID%3DearlyAccess%26segmentName%3DholidayReserve%23utm_source%3Dsamsung%23utm_medium%3Demail%23utm_campaign%3Dholiday_deals_t3_11172020%23marsLinkCategory%3D__MARSTRACKING__%23MKM_RID%3D__BPNUMBER__%23MKM_MID%3D__DELIVERNAME__%23cid%3D__CID____SEGMENTCODE__%23bpid%3D__BPNUMBER__&afl=https%3A%2F%2Fwww.samsung.com%2Fus%2Fmobile%2Fphones%2Fgalaxy-a%2Fbuy%2F%3Flink%3Dgalaxy-a71-5g%26offerCID%3DearlyAccess%26utm_source%3Dsamsung%26utm_medium%3Demail%26utm_campaign%3Dholiday_deals_t3_11172020%26marsLinkCategory%3D__MARSTRACKING__%26MKM_RID%3D__BPNUMBER__%26MKM_MID%3D__DELIVERNAME__%26cid%3D__CID____SEGMENTCODE__%26bpid%3D__BPNUMBER__&efr=1 | CD4: =DDOfferCopy!L7 -> NULL | ... CF4: =DDOfferCopy!N7 -> NULL | CG4: GIFT GUIDE | CH4: =MiscBanners!$H$4 -> Give-wonder-500xV.jpg | CI4: =MiscBanners!$I$4 -> The gift that keeps on giving | CJ4: =MiscBanners!$J$4 -> NULL | CK4: =MiscBanners!$K$4 -> Discover even more exclusive offers on your favorite products and unlock the power of smart and savvy gifting. | CL4: =MiscBanners!$L$4 -> Shop now | CM4: =MiscBanners!$M$4 -> https://www.samsung.com/us/gift-ideas/ | CN4: =MiscBanners!$N$4 -> https://shopsamsung.page.link?link=https%3A%2F%2Fwww.samsung.com%2Fus%2Fgift-ideas%2F%3FofferCID%3DearlyAccess%26utm_source%3Dsamsung%26utm_medium%3Demail%26utm_campaign%3Dholiday_deals_t3_11172020%26marsLinkCategory%3D__MARSTRACKING__%26MKM_RID%3D__BPNUMBER__%26MKM_MID%3D__DELIVERNAME__%26cid%3D__CID____SEGMENTCODE__%26bpid%3D__BPNUMBER__%26iosparam%3Dsamsungestore%25253A%25252F%25252Fopenwebview%252523url%25253Dhttps%25253A%25252F%25252Fwww.samsung.com%25252Fus%25252Fapp%25252Fgift-ideas%25252F%25253FofferCID%25253DearlyAccess%252526segmentName%25253DholidayReserve%252523utm_source%25253Dsamsung%252523utm_medium%25253Demail%252523utm_campaign%25253Dholiday_deals_t3_11172020%252523marsLinkCategory%25253D__MARSTRACKING__%252523MKM_RID%25253D__BPNUMBER__%252523MKM_MID%25253D__DELIVERNAME__%252523cid%25253D__CID____SEGMENTCODE__%252523bpid%25253D__BPNUMBER__&utm_source=samsung&utm_medium=email&utm_campaign=holiday_deals_t3_11172020&marsLinkCategory=__MARSTRACKING__&MKM_RID=__BPNUMBER__&MKM_MID=__DELIVERNAME__&cid=__CID____SEGMENTCODE__&bpid=__BPNUMBER__&apn=com.samsung.ecomm&al=samsungestore%3A%2F%2Fopenwebview%23url%3Dhttps%3A%2F%2Fwww.samsung.com%2Fus%2Fapp%2Fgift-ideas%2F%3FofferCID%3DearlyAccess%26segmentName%3DholidayReserve%23utm_source%3Dsamsung%23utm_medium%3Demail%23utm_campaign%3Dholiday_deals_t3_11172020%23marsLinkCategory%3D__MARSTRACKING__%23MKM_RID%3D__BPNUMBER__%23MKM_MID%3D__DELIVERNAME__%23cid%3D__CID____SEGMENTCODE__%23bpid%3D__BPNUMBER__&afl=https%3A%2F%2Fwww.samsung.com%2Fus%2Fgift-ideas%2F%3FofferCID%3DearlyAccess%26utm_source%3Dsamsung%26utm_medium%3Demail%26utm_campaign%3Dholiday_deals_t3_11172020%26marsLinkCategory%3D__MARSTRACKING__%26MKM_RID%3D__BPNUMBER__%26MKM_MID%3D__DELIVERNAME__%26cid%3D__CID____SEGMENTCODE__%26bpid%3D__BPNUMBER__&isi=1274679179&ibi=com.samsung.ShopSamsung&ius=samsungestore&ifl=https%3A%2F%2Fwww.samsung.com%2Fus%2Fgift-ideas%2F%3FofferCID%3DearlyAccess%26utm_source%3Dsamsung%26utm_medium%3Demail%26utm_campaign%3Dholiday_deals_t3_11172020%26marsLinkCategory%3D__MARSTRACKING__%26MKM_RID%3D__BPNUMBER__%26MKM_MID%3D__DELIVERNAME__%26cid%3D__CID____SEGMENTCODE__%26bpid%3D__BPNUMBER__&efr=1 | CO4: =MiscBanners!$O$4 -> NULL | CP4: =MiscBanners!$P$4 -> NULL | CQ4: =MiscBanners!$Q$4 -> NULL | CR4: FOOTER | DC4: TC 1 | DD4: =TC!B2 -> NULL | DE4: =TC!C2 -> NULL | DF4: =TC!D2 -> NULL | DG4: =TC!E2 -> ᶿFor a limited time only, on Samsung.com/Shop Samsung App, pre-order or purchase a new qualifying Galaxy device (“Qualifying Purchase”), send in your qualifying trade-in device to Samsung through the Samsung Trade-In Program, and if Samsung determines your trade-in device meets all eligibility requirements, you will receive a trade-in credit specific to your qualifying trade-in device to apply toward your Qualifying Purchase. Device models that currently qualify for trade-in and trade-in credit amounts associated with those models are available on Samsung.com and the Shop Samsung App; eligible models and amounts may change at Samsung’s sole discretion. To be eligible for trade-in, your qualifying device must meet all Trade-In Program eligibility requirements, which include, but are not limited to, that the device powers on, holds a charge, and does not power off unexpectedly; has a functioning display; has no breaks or cracks in the screen (unless a cracked screen offer applies); has no breaks or cracks in the case; has no liquid damage (whether visible or not); has no other defects that go beyond normal wear and tear; is not on a black list; has a verified FCC ID; has been reset to factory settings; has all personal information removed; has all software locks disabled; and is owned by you (leased devices are not eligible). Anticipated trade-in value will be applied as a credit at time of purchase, but, if you do not send in your trade-in device within 15 days of receipt of your Qualifying Purchase, you will be charged back for the trade-in credit applied to your purchase, or if you send in your trade-in device within 15 days of receipt of your Qualifying Purchase but Samsung determines your device does not meet all eligibility requirements, you will be charged back for the trade-in credit applied to your purchase minus $25. Participation in this program does not excuse you from contracts with your carrier or retailer (or any related payments or fees) for the device that was traded in. Limit 1 trade-in per Qualifying Purchase. Samsung reserves the right to modify or discontinue this offer at any time. The Trade-In Program cannot be combined with any other Samsung, carrier or retailer promotions, discounts, or offers unless specifically provided for in the terms and conditions of such offers. Additional terms, including terms that govern the resolution of disputes, apply. Click here to learn more. | DH4: =TC!F2 -> NULL | DI4: =TC!G2 -> https://www.samsung.com/us/trade-in/terms-and-conditions/ | DJ4: =TC!H2 -> 0 | DK4: =TC!I2 -> NULL | ... DM4: =TC!K2 -> NULL | DN4: TC2 | DO4: =TC!B3 -> NULL | DP4: =TC!C3 -> NULL | DQ4: =TC!D3 -> NULL | DR4: =TC!E3 -> ⊕0% APR for 24, 36, 40 or 48 Months with Equal Payments: Available on purchases of select products charged to a Samsung Financing account. Minimum purchase: $50. 0% APR from date of eligible purchase until paid in full. Estimated monthly payment equals the eligible purchase amount multiplied by a repayment factor and rounded to the nearest penny (repayment factors: .04167 for 24 month, .02778 for 36 month, .02500 for 40 month, .02083 for 48 month). Last payment may vary due to rounding. Total amount of payments will not exceed eligible purchase amount. Other transactions and fees affect overall minimum payment amount. Advertised payment amount is an estimate and may change once taxes, delivery or other charges are added. Limited time offer. Regular account terms apply to non-promo purchases. Minimum interest charge: $1. Standard Purchase APR: 29.99%. Prior purchases excluded. Account must be in good standing. Subject to credit approval. Samsung Financing account issued by TD Bank, N.A. | DS4: =TC!F3 -> NULL | DT4: =TC!G3 -> 0 | DU4: =TC!H3 -> 0 | DV4: =TC!I3 -> NULL | ... DX4: =TC!K3 -> NULL | DY4: TC3 | DZ4: =TC!B4 -> NULL | EA4: =TC!C4 -> NULL | EB4: =TC!D4 -> NULL | EC4: =TC!E4 -> §18+ & 50 US/DC only. By 11/29/2020 11:59 PM EST, purchase a qualifying device on device installment plan, 2-year contract plan, lease or outright purchase at full retail price (“Qualifying Purchase”), & receive a Samsung Credit of $100 (“Gift”) instant credit from Samsung for use towards an eligible purchase including select wearables, tablets, PC’s and accessories when you purchase qualifying smartphone (“Qualifying Purchase”) before 01/15/21 at 11:59 PM EST. You must make a Qualifying Purchase on Samsung.com or the Shop Samsung App to receive an instant credit which may be applied instantly or deferred to a future eligible purchase. Gift valid for use on eligible purchases from 11/10/20- 01/15/21 or while supplies last, and is a one-time use certificate; when first used, any value not used is lost. Gift is non-transferrable and limited to 1 instant credit per registered customer. Samsung Credits are valid only at www.Samsung.com or in the App for use towards an eligible purchase. Void where prohibited or restricted by law. Additional restrictions apply. Offer subject to additional terms here. Samsung reserves the right to modify or discontinue offer at any time by posting notice on the app or website | ED4: =TC!F4 -> NULL | EE4: =TC!G4 -> https://www.samsung.com/us/ | EF4: =TC!H4 -> 0 | EG4: =TC!I4 -> NULL | ... EI4: =TC!K4 -> NULL | EJ4: TC4 | EK4: =TC!B5 -> NULL | EL4: =TC!C5 -> NULL | EM4: =TC!D5 -> NULL | EN4: =TC!E5 -> †18+ & 50 US/DC only. By 11/29/2020 11:59 PM EST, purchase a qualifying device on device installment plan, 2-year contract plan, lease or outright purchase at full retail price (“Qualifying Purchase”), & receive a Samsung Credit of $30 (“Gift”) instant credit from Samsung for use towards an eligible purchase including select wearables, tablets, PC’s and accessories when you purchase qualifying smartphone (“Qualifying Purchase”) before 01/15/21 at 11:59 PM EST. You must make a Qualifying Purchase on Samsung.com or the Shop Samsung App to receive an instant credit which may be applied instantly or deferred to a future eligible purchase. Gift valid for use on eligible purchases from 11/10/20- 01/15/21 or while supplies last, and is a one-time use certificate; when first used, any value not used is lost. Gift is non-transferrable and limited to 1 instant credit per registered customer. Samsung Credits are valid only at www.Samsung.com or in the App for use towards an eligible purchase. Void where prohibited or restricted by law. Additional restrictions apply. Offer subject to additional terms here. Samsung reserves the right to modify or discontinue offer at any time by posting notice on the app or website | EO4: =TC!F5 -> NULL | EP4: =TC!G5 -> https://www.samsung.com/us/ | EQ4: =TC!H5 -> 0 | ER4: =TC!I5 -> NULL | ... ET4: =TC!K5 -> NULL | EU4: TC5 | EV4: =TC!B6 -> NULL | EW4: =TC!C6 -> NULL | EX4: =TC!D6 -> NULL | EY4: =TC!E6 -> ‡18+ & 50 US/DC only. Between 10/26/20 at 12:01 AM EST and 11/18/20 at 11:59 PM EST (“Registration Period”), register for the Samsung Holiday instant credit promotion to receive a $20 instant credit from Samsung for use towards an eligible purchase including select wearables, tablets, PC’s and accessories when you purchase qualifying smartphone (“Qualifying Purchase”) before 01/15/21 at 11:59 PM EST. You must make a Qualifying Purchase on Samsung.com or the Shop Samsung App to receive an instant credit which may be applied instantly or deferred to a future eligible purchase. Gift valid for use on eligible purchases from 11/10/20- 01/15/21 or while supplies last, and is a one-time use certificate; when first used, any value not used is lost. Gift is non-transferrable and limited to 1 instant credit per registered customer. Samsung Credits are valid only at www.Samsung.com or in the App for use towards an eligible purchase. Void where prohibited or restricted by law. Additional restrictions apply. Offer subject to additional terms here. Samsung reserves the right to modify or discontinue offer at any time by posting notice on the app or website. | EZ4: =TC!F6 -> NULL | FA4: =TC!G6 -> https://www.samsung.com/us/ | FB4: =TC!H6 -> 0 | FC4: =TC!I6 -> NULL | ... FE4: =TC!K6 -> NULL
A5: DD | B5: MB_GALAXY MB_FOLD MB_NOTE MB_MID | C5: X | D5: X | E5: Non_Reservers EPP_NonReservers | G5: Cyber Monday is on. | H5: Act fast to save on showstopping gifts while supplies last. | I5: EPP Banner | J5: NULL | K5: NULL | L5: NULL | M5: NULL | N5: NULL | O5: NULL | P5: NULL | Q5: NULL | R5: NULL | S5: Hero & Countdown Timer Image | T5: ='Dynamic Banners'!$L$4 -> Cyber-monday-1.png | U5: ='Dynamic Banners'!$M$4 -> The clock is ticking away for Cyber Monday | V5: NULL | W5: ='Dynamic Banners'!$N$4 -> Shop amazing offers on showstopping products while supplies last. | X5: NULL | Y5: =[1]MiscBanners!$B$4 -> https://www.samsung.com/us/shop/all-deals/ | Z5: =[1]MiscBanners!$C$4 -> https://shopsamsung.page.link?link=https%3A%2F%2Fwww.samsung.com%2Fus%2Fshop%2Fall-deals%2F%3FofferCID%3DearlyAccess%26utm_source%3Dsamsung%26utm_medium%3Demail%26utm_campaign%3Dholiday_deals_t3_11172020%26marsLinkCategory%3D__MARSTRACKING__%26MKM_RID%3D__BPNUMBER__%26MKM_MID%3D__DELIVERNAME__%26cid%3D__CID____SEGMENTCODE__%26bpid%3D__BPNUMBER__%26iosparam%3Dsamsungestore%25253A%25252F%25252Fgototab%252523tab%25253D4%252523offerCID%25253DearlyAccess%252523utm_source%25253Dsamsung%252523utm_medium%25253Demail%252523utm_campaign%25253Dholiday_deals_t3_11172020%252523marsLinkCategory%25253D__MARSTRACKING__%252523MKM_RID%25253D__BPNUMBER__%252523MKM_MID%25253D__DELIVERNAME__%252523cid%25253D__CID____SEGMENTCODE__%252523bpid%25253D__BPNUMBER__&utm_source=samsung&utm_medium=email&utm_campaign=holiday_deals_t3_11172020&marsLinkCategory=__MARSTRACKING__&MKM_RID=__BPNUMBER__&MKM_MID=__DELIVERNAME__&cid=__CID____SEGMENTCODE__&bpid=__BPNUMBER__&apn=com.samsung.ecomm&al=samsungestore%3A%2F%2Fgototab%23tab%3D4%23offerCID%3DearlyAccess%23utm_source%3Dsamsung%23utm_medium%3Demail%23utm_campaign%3Dholiday_deals_t3_11172020%23marsLinkCategory%3D__MARSTRACKING__%23MKM_RID%3D__BPNUMBER__%23MKM_MID%3D__DELIVERNAME__%23cid%3D__CID____SEGMENTCODE__%23bpid%3D__BPNUMBER__&afl=https%3A%2F%2Fwww.samsung.com%2Fus%2Fshop%2Fall-deals%2F%3FofferCID%3DearlyAccess%26utm_source%3Dsamsung%26utm_medium%3Demail%26utm_campaign%3Dholiday_deals_t3_11172020%26marsLinkCategory%3D__MARSTRACKING__%26MKM_RID%3D__BPNUMBER__%26MKM_MID%3D__DELIVERNAME__%26cid%3D__CID____SEGMENTCODE__%26bpid%3D__BPNUMBER__&isi=1274679179&ibi=com.samsung.ShopSamsung&ius=samsungestore&ifl=https%3A%2F%2Fwww.samsung.com%2Fus%2Fshop%2Fall-deals%2F%3FofferCID%3DearlyAccess%26utm_source%3Dsamsung%26utm_medium%3Demail%26utm_campaign%3Dholiday_deals_t3_11172020%26marsLinkCategory%3D__MARSTRACKING__%26MKM_RID%3D__BPNUMBER__%26MKM_MID%3D__DELIVERNAME__%26cid%3D__CID____SEGMENTCODE__%26bpid%3D__BPNUMBER__&efr=1 | AA5: NULL | AB5: NULL | AC5: NULL | AD5: Hero & Countdown Timer Copy | AE5: NULL | AF5: NULL | AG5: While supplies last. | AH5: Today is your day to shop some of our greatest offers of the year. Plus, unlock $30 or more instant credit with any smartphone purchase.§† | AI5: NULL | AJ5: =[1]MiscBanners!$B$4 -> https://www.samsung.com/us/shop/all-deals/ | AK5: =[1]MiscBanners!$C$4 -> https://shopsamsung.page.link?link=https%3A%2F%2Fwww.samsung.com%2Fus%2Fshop%2Fall-deals%2F%3FofferCID%3DearlyAccess%26utm_source%3Dsamsung%26utm_medium%3Demail%26utm_campaign%3Dholiday_deals_t3_11172020%26marsLinkCategory%3D__MARSTRACKING__%26MKM_RID%3D__BPNUMBER__%26MKM_MID%3D__DELIVERNAME__%26cid%3D__CID____SEGMENTCODE__%26bpid%3D__BPNUMBER__%26iosparam%3Dsamsungestore%25253A%25252F%25252Fgototab%252523tab%25253D4%252523offerCID%25253DearlyAccess%252523utm_source%25253Dsamsung%252523utm_medium%25253Demail%252523utm_campaign%25253Dholiday_deals_t3_11172020%252523marsLinkCategory%25253D__MARSTRACKING__%252523MKM_RID%25253D__BPNUMBER__%252523MKM_MID%25253D__DELIVERNAME__%252523cid%25253D__CID____SEGMENTCODE__%252523bpid%25253D__BPNUMBER__&utm_source=samsung&utm_medium=email&utm_campaign=holiday_deals_t3_11172020&marsLinkCategory=__MARSTRACKING__&MKM_RID=__BPNUMBER__&MKM_MID=__DELIVERNAME__&cid=__CID____SEGMENTCODE__&bpid=__BPNUMBER__&apn=com.samsung.ecomm&al=samsungestore%3A%2F%2Fgototab%23tab%3D4%23offerCID%3DearlyAccess%23utm_source%3Dsamsung%23utm_medium%3Demail%23utm_campaign%3Dholiday_deals_t3_11172020%23marsLinkCategory%3D__MARSTRACKING__%23MKM_RID%3D__BPNUMBER__%23MKM_MID%3D__DELIVERNAME__%23cid%3D__CID____SEGMENTCODE__%23bpid%3D__BPNUMBER__&afl=https%3A%2F%2Fwww.samsung.com%2Fus%2Fshop%2Fall-deals%2F%3FofferCID%3DearlyAccess%26utm_source%3Dsamsung%26utm_medium%3Demail%26utm_campaign%3Dholiday_deals_t3_11172020%26marsLinkCategory%3D__MARSTRACKING__%26MKM_RID%3D__BPNUMBER__%26MKM_MID%3D__DELIVERNAME__%26cid%3D__CID____SEGMENTCODE__%26bpid%3D__BPNUMBER__&isi=1274679179&ibi=com.samsung.ShopSamsung&ius=samsungestore&ifl=https%3A%2F%2Fwww.samsung.com%2Fus%2Fshop%2Fall-deals%2F%3FofferCID%3DearlyAccess%26utm_source%3Dsamsung%26utm_medium%3Demail%26utm_campaign%3Dholiday_deals_t3_11172020%26marsLinkCategory%3D__MARSTRACKING__%26MKM_RID%3D__BPNUMBER__%26MKM_MID%3D__DELIVERNAME__%26cid%3D__CID____SEGMENTCODE__%26bpid%3D__BPNUMBER__&efr=1 | AL5: NULL | AM5: NULL | AN5: NULL | AO5: N20F (N20/N20U) | AP5: =DDOfferCopy!E4 -> 22_IM_HeadImage_MB_Note-500xV.jpg | AQ5: =DDOfferCopy!F4 -> Get up to 70% off Galaxy Note 20 5G or Note 20 Ultra 5G | AR5: =DDOfferCopy!G4 -> Now from only $8.34/mo for 36 mos⊕ or $299.99 with eligible trade-in.ᶿ | AS5: =DDOfferCopy!H4 -> Get $150 off instantly and up to $550 trade-in credit.ᶿ | AT5: =DDOfferCopy!I4 -> Buy now | AU5: =DDOfferCopy!P4 -> https://www.samsung.com/us/smartphones/galaxy-note20-5g/buy/ | AV5: =DDOfferCopy!$Q$4 -> https://shopsamsung.page.link?link=https%3A%2F%2Fwww.samsung.com%2Fus%2Fsmartphones%2Fgalaxy-note20-5g%2Fbuy%2F%3Futm_source%3Dsamsung%26utm_medium%3Demail%26utm_campaign%3Dholiday_deals_t3_11172020%26marsLinkCategory%3D__MARSTRACKING__%26MKM_RID%3D__BPNUMBER__%26MKM_MID%3D__DELIVERNAME__%26cid%3D__CID____SEGMENTCODE__%26bpid%3D__BPNUMBER__&utm_source=samsung&utm_medium=email&utm_campaign=holiday_deals_t3_11172020&marsLinkCategory=__MARSTRACKING__&MKM_RID=__BPNUMBER__&MKM_MID=__DELIVERNAME__&cid=__CID____SEGMENTCODE__&bpid=__BPNUMBER__&apn=com.samsung.ecomm&al=samsungestore%3A%2F%2Fopenwebview%23url%3Dhttps%3A%2F%2Fwww.samsung.com%2Fus%2Fbuy%2Fsmartphones%2Fgalaxy-note20-5g%2Findex.html%23utm_source%3Dsamsung%23utm_medium%3Demail%23utm_campaign%3Dholiday_deals_t3_11172020%23marsLinkCategory%3D__MARSTRACKING__%23MKM_RID%3D__BPNUMBER__%23MKM_MID%3D__DELIVERNAME__%23cid%3D__CID____SEGMENTCODE__%23bpid%3D__BPNUMBER__&afl=https%3A%2F%2Fwww.samsung.com%2Fus%2Fsmartphones%2Fgalaxy-note20-5g%2Fbuy%2F%3Futm_source%3Dsamsung%26utm_medium%3Demail%26utm_campaign%3Dholiday_deals_t3_11172020%26marsLinkCategory%3D__MARSTRACKING__%26MKM_RID%3D__BPNUMBER__%26MKM_MID%3D__DELIVERNAME__%26cid%3D__CID____SEGMENTCODE__%26bpid%3D__BPNUMBER__&efr=1 | AW5: =DDOfferCopy!R4 -> NULL | AX5: =DDOfferCopy!S4 -> NULL | AY5: =DDOfferCopy!T4 -> NULL | AZ5: S20 Family (S20+, S20U, S20, S20FE) | BA5: =DDOfferCopy!E5 -> 21_IM_HeadImage_MB_Galaxy-500xV.jpg | BB5: =DDOfferCopy!F5 -> Get up to 73% off Galaxy S20 5G series devices | BC5: =DDOfferCopy!G5 -> Now from only $7.92/mo for 24 mos⊕ or $189.99 with eligible trade-in.ᶿ | BD5: =DDOfferCopy!H5 -> Get up to $150 off instantly and up to $460 trade-in credit.ᶿ | BE5: =DDOfferCopy!I5 -> Buy now | BF5: =DDOfferCopy!J5 -> https://www.samsung.com/us/mobile/galaxy-s20-5g/buy/ | BG5: =DDOfferCopy!K5 -> https://shopsamsung.page.link?link=https%3A%2F%2Fwww.samsung.com%2Fus%2Fmobile%2Fgalaxy-s20-5g%2Fbuy%2F%3FofferCID%3DearlyAccess%26utm_source%3Dsamsung%26utm_medium%3Demail%26utm_campaign%3Dholiday_deals_t3_11172020%26marsLinkCategory%3D__MARSTRACKING__%26MKM_RID%3D__BPNUMBER__%26MKM_MID%3D__DELIVERNAME__%26cid%3D__CID____SEGMENTCODE__%26bpid%3D__BPNUMBER__&utm_source=samsung&utm_medium=email&utm_campaign=holiday_deals_t3_11172020&marsLinkCategory=__MARSTRACKING__&MKM_RID=__BPNUMBER__&MKM_MID=__DELIVERNAME__&cid=__CID____SEGMENTCODE__&bpid=__BPNUMBER__&apn=com.samsung.ecomm&al=samsungestore%3A%2F%2Fopenwebview%23url%3Dhttps%3A%2F%2Fwww.samsung.com%2Fus%2Fbuy%2Fsmartphones%2Fgalaxy-s20-5g%2Findex.html%3FofferCID%3DearlyAccess%26segmentName%3DholidayReserve%23utm_source%3Dsamsung%23utm_medium%3Demail%23utm_campaign%3Dholiday_deals_t3_11172020%23marsLinkCategory%3D__MARSTRACKING__%23MKM_RID%3D__BPNUMBER__%23MKM_MID%3D__DELIVERNAME__%23cid%3D__CID____SEGMENTCODE__%23bpid%3D__BPNUMBER__&afl=https%3A%2F%2Fwww.samsung.com%2Fus%2Fmobile%2Fgalaxy-s20-5g%2Fbuy%2F%3FofferCID%3DearlyAccess%26utm_source%3Dsamsung%26utm_medium%3Demail%26utm_campaign%3Dholiday_deals_t3_11172020%26marsLinkCategory%3D__MARSTRACKING__%26MKM_RID%3D__BPNUMBER__%26MKM_MID%3D__DELIVERNAME__%26cid%3D__CID____SEGMENTCODE__%26bpid%3D__BPNUMBER__&efr=1 | BH5: =DDOfferCopy!L5 -> NULL | ... BJ5: =DDOfferCopy!N5 -> NULL | BK5: Fold2 | BL5: =DDOfferCopy!E6 -> 23_IM_HeadImage_MB_Fold-500xV.jpg | BM5: =DDOfferCopy!F6 -> Get up to 50% off Galaxy Z Fold2 5G | BN5: =DDOfferCopy!G6 -> Now from only $20.84/mo for 48 mos⊕ or $999.99 with eligible trade-in.ᶿ | BO5: =DDOfferCopy!H6 -> Our best Galaxy Z Fold2 5G offer of the year. Get up to $1000 trade-in credit.ᶿ Plus, get up to $120 instant credit toward accessories.§‡ | BP5: =DDOfferCopy!I6 -> Buy now | BQ5: =DDOfferCopy!J6 -> https://www.samsung.com/us/smartphones/galaxy-z-fold2-5g/buy/ | BR5: =DDOfferCopy!K6 -> https://shopsamsung.page.link?link=https%3A%2F%2Fwww.samsung.com%2Fus%2Fsmartphones%2Fgalaxy-z-fold2-5g%2Fbuy%2F%3FofferCID%3DearlyAccess%26utm_source%3Dsamsung%26utm_medium%3Demail%26utm_campaign%3Dholiday_deals_t3_11172020%26marsLinkCategory%3D__MARSTRACKING__%26MKM_RID%3D__BPNUMBER__%26MKM_MID%3D__DELIVERNAME__%26cid%3D__CID____SEGMENTCODE__%26bpid%3D__BPNUMBER__&utm_source=samsung&utm_medium=email&utm_campaign=holiday_deals_t3_11172020&marsLinkCategory=__MARSTRACKING__&MKM_RID=__BPNUMBER__&MKM_MID=__DELIVERNAME__&cid=__CID____SEGMENTCODE__&bpid=__BPNUMBER__&apn=com.samsung.ecomm&al=samsungestore%3A%2F%2Fopenwebview%23url%3Dhttps%3A%2F%2Fwww.samsung.com%2Fus%2Fbuy%2Fsmartphones%2Fgalaxy-z-fold2-5g%2Findex.html%3FofferCID%3DearlyAccess%26segmentName%3DholidayReserve%23utm_source%3Dsamsung%23utm_medium%3Demail%23utm_campaign%3Dholiday_deals_t3_11172020%23marsLinkCategory%3D__MARSTRACKING__%23MKM_RID%3D__BPNUMBER__%23MKM_MID%3D__DELIVERNAME__%23cid%3D__CID____SEGMENTCODE__%23bpid%3D__BPNUMBER__&afl=https%3A%2F%2Fwww.samsung.com%2Fus%2Fsmartphones%2Fgalaxy-z-fold2-5g%2Fbuy%2F%3FofferCID%3DearlyAccess%26utm_source%3Dsamsung%26utm_medium%3Demail%26utm_campaign%3Dholiday_deals_t3_11172020%26marsLinkCategory%3D__MARSTRACKING__%26MKM_RID%3D__BPNUMBER__%26MKM_MID%3D__DELIVERNAME__%26cid%3D__CID____SEGMENTCODE__%26bpid%3D__BPNUMBER__&efr=1 | BS5: =DDOfferCopy!L6 -> NULL | ... BU5: =DDOfferCopy!N6 -> NULL | BV5: A71 5G / A51 5G | BW5: =DDOfferCopy!E7 -> 24-IM-A71-A51-HeadImage-500xV.jpg | BX5: =DDOfferCopy!F7 -> Get 50% off Galaxy A71 5G with T-Mobile and Verizon | BY5: =DDOfferCopy!G7 -> Now from only only $8.34/mo for 36 mos⊕ or $299.99 with eligible trade-in.ᶿ | BZ5: =DDOfferCopy!H7 -> Save up to $250 instantly and get $75 or more trade-in credit. Treat yourself to blazing fast 5G speeds and incredible features at an amazing value. | CA5: =DDOfferCopy!I7 -> Buy now | CB5: =DDOfferCopy!J7 -> https://www.samsung.com/us/mobile/phones/galaxy-a/buy/?link=galaxy-a71-5g | CC5: =DDOfferCopy!K7 -> https://shopsamsung.page.link?link=https%3A%2F%2Fwww.samsung.com%2Fus%2Fmobile%2Fphones%2Fgalaxy-a%2Fbuy%2F%3Flink%3Dgalaxy-a71-5g%26offerCID%3DearlyAccess%26utm_source%3Dsamsung%26utm_medium%3Demail%26utm_campaign%3Dholiday_deals_t3_11172020%26marsLinkCategory%3D__MARSTRACKING__%26MKM_RID%3D__BPNUMBER__%26MKM_MID%3D__DELIVERNAME__%26cid%3D__CID____SEGMENTCODE__%26bpid%3D__BPNUMBER__&utm_source=samsung&utm_medium=email&utm_campaign=holiday_deals_t3_11172020&marsLinkCategory=__MARSTRACKING__&MKM_RID=__BPNUMBER__&MKM_MID=__DELIVERNAME__&cid=__CID____SEGMENTCODE__&bpid=__BPNUMBER__&apn=com.samsung.ecomm&al=samsungestore%3A%2F%2Fopenwebview%23url%3Dhttps%3A%2F%2Fwww.samsung.com%2Fus%2Fbuy%2Fsmartphones%2Fgalaxy-a50%2Findex.html%3Flink%3Dgalaxy-a71-5g%26offerCID%3DearlyAccess%26segmentName%3DholidayReserve%23utm_source%3Dsamsung%23utm_medium%3Demail%23utm_campaign%3Dholiday_deals_t3_11172020%23marsLinkCategory%3D__MARSTRACKING__%23MKM_RID%3D__BPNUMBER__%23MKM_MID%3D__DELIVERNAME__%23cid%3D__CID____SEGMENTCODE__%23bpid%3D__BPNUMBER__&afl=https%3A%2F%2Fwww.samsung.com%2Fus%2Fmobile%2Fphones%2Fgalaxy-a%2Fbuy%2F%3Flink%3Dgalaxy-a71-5g%26offerCID%3DearlyAccess%26utm_source%3Dsamsung%26utm_medium%3Demail%26utm_campaign%3Dholiday_deals_t3_11172020%26marsLinkCategory%3D__MARSTRACKING__%26MKM_RID%3D__BPNUMBER__%26MKM_MID%3D__DELIVERNAME__%26cid%3D__CID____SEGMENTCODE__%26bpid%3D__BPNUMBER__&efr=1 | CD5: =DDOfferCopy!L7 -> NULL | ... CF5: =DDOfferCopy!N7 -> NULL | CG5: GIFT GUIDE | CH5: =MiscBanners!$H$4 -> Give-wonder-500xV.jpg | CI5: =MiscBanners!$I$4 -> The gift that keeps on giving | CJ5: =MiscBanners!$J$4 -> NULL | CK5: =MiscBanners!$K$4 -> Discover even more exclusive offers on your favorite products and unlock the power of smart and savvy gifting. | CL5: =MiscBanners!$L$4 -> Shop now | CM5: =MiscBanners!$M$4 -> https://www.samsung.com/us/gift-ideas/ | CN5: =MiscBanners!$N$4 -> https://shopsamsung.page.link?link=https%3A%2F%2Fwww.samsung.com%2Fus%2Fgift-ideas%2F%3FofferCID%3DearlyAccess%26utm_source%3Dsamsung%26utm_medium%3Demail%26utm_campaign%3Dholiday_deals_t3_11172020%26marsLinkCategory%3D__MARSTRACKING__%26MKM_RID%3D__BPNUMBER__%26MKM_MID%3D__DELIVERNAME__%26cid%3D__CID____SEGMENTCODE__%26bpid%3D__BPNUMBER__%26iosparam%3Dsamsungestore%25253A%25252F%25252Fopenwebview%252523url%25253Dhttps%25253A%25252F%25252Fwww.samsung.com%25252Fus%25252Fapp%25252Fgift-ideas%25252F%25253FofferCID%25253DearlyAccess%252526segmentName%25253DholidayReserve%252523utm_source%25253Dsamsung%252523utm_medium%25253Demail%252523utm_campaign%25253Dholiday_deals_t3_11172020%252523marsLinkCategory%25253D__MARSTRACKING__%252523MKM_RID%25253D__BPNUMBER__%252523MKM_MID%25253D__DELIVERNAME__%252523cid%25253D__CID____SEGMENTCODE__%252523bpid%25253D__BPNUMBER__&utm_source=samsung&utm_medium=email&utm_campaign=holiday_deals_t3_11172020&marsLinkCategory=__MARSTRACKING__&MKM_RID=__BPNUMBER__&MKM_MID=__DELIVERNAME__&cid=__CID____SEGMENTCODE__&bpid=__BPNUMBER__&apn=com.samsung.ecomm&al=samsungestore%3A%2F%2Fopenwebview%23url%3Dhttps%3A%2F%2Fwww.samsung.com%2Fus%2Fapp%2Fgift-ideas%2F%3FofferCID%3DearlyAccess%26segmentName%3DholidayReserve%23utm_source%3Dsamsung%23utm_medium%3Demail%23utm_campaign%3Dholiday_deals_t3_11172020%23marsLinkCategory%3D__MARSTRACKING__%23MKM_RID%3D__BPNUMBER__%23MKM_MID%3D__DELIVERNAME__%23cid%3D__CID____SEGMENTCODE__%23bpid%3D__BPNUMBER__&afl=https%3A%2F%2Fwww.samsung.com%2Fus%2Fgift-ideas%2F%3FofferCID%3DearlyAccess%26utm_source%3Dsamsung%26utm_medium%3Demail%26utm_campaign%3Dholiday_deals_t3_11172020%26marsLinkCategory%3D__MARSTRACKING__%26MKM_RID%3D__BPNUMBER__%26MKM_MID%3D__DELIVERNAME__%26cid%3D__CID____SEGMENTCODE__%26bpid%3D__BPNUMBER__&isi=1274679179&ibi=com.samsung.ShopSamsung&ius=samsungestore&ifl=https%3A%2F%2Fwww.samsung.com%2Fus%2Fgift-ideas%2F%3FofferCID%3DearlyAccess%26utm_source%3Dsamsung%26utm_medium%3Demail%26utm_campaign%3Dholiday_deals_t3_11172020%26marsLinkCategory%3D__MARSTRACKING__%26MKM_RID%3D__BPNUMBER__%26MKM_MID%3D__DELIVERNAME__%26cid%3D__CID____SEGMENTCODE__%26bpid%3D__BPNUMBER__&efr=1 | CO5: =MiscBanners!$O$4 -> NULL | CP5: =MiscBanners!$P$4 -> NULL | CQ5: =MiscBanners!$Q$4 -> NULL | CR5: FOOTER | DC5: TC 1 | DD5: NULL | DE5: NULL | DF5: NULL | DG5: ᶿFor a limited time only, on Samsung.com/Shop Samsung App, pre-order or purchase a new qualifying Galaxy device (“Qualifying Purchase”), send in your qualifying trade-in device to Samsung through the Samsung Trade-In Program, and if Samsung determines your trade-in device meets all eligibility requirements, you will receive a trade-in credit specific to your qualifying trade-in device to apply toward your Qualifying Purchase. Device models that currently qualify for trade-in and trade-in credit amounts associated with those models are available on Samsung.com and the Shop Samsung App; eligible models and amounts may change at Samsung’s sole discretion. To be eligible for trade-in, your qualifying device must meet all Trade-In Program eligibility requirements, which include, but are not limited to, that the device powers on, holds a charge, and does not power off unexpectedly; has a functioning display; has no breaks or cracks in the screen (unless a cracked screen offer applies); has no breaks or cracks in the case; has no liquid damage (whether visible or not); has no other defects that go beyond normal wear and tear; is not on a black list; has a verified FCC ID; has been reset to factory settings; has all personal information removed; has all software locks disabled; and is owned by you (leased devices are not eligible). Anticipated trade-in value will be applied as a credit at time of purchase, but, if you do not send in your trade-in device within 15 days of receipt of your Qualifying Purchase, you will be charged back for the trade-in credit applied to your purchase, or if you send in your trade-in device within 15 days of receipt of your Qualifying Purchase but Samsung determines your device does not meet all eligibility requirements, you will be charged back for the trade-in credit applied to your purchase minus $25. Participation in this program does not excuse you from contracts with your carrier or retailer (or any related payments or fees) for the device that was traded in. Limit 1 trade-in per Qualifying Purchase. Samsung reserves the right to modify or discontinue this offer at any time. The Trade-In Program cannot be combined with any other Samsung, carrier or retailer promotions, discounts, or offers unless specifically provided for in the terms and conditions of such offers. Additional terms, including terms that govern the resolution of disputes, apply. Click here to learn more. | DH5: NULL | DI5: https://www.samsung.com/us/trade-in/terms-and-conditions/ | DJ5: 0 | DK5: NULL | DL5: NULL | DM5: NULL | DN5: TC2 | DO5: NULL | DP5: NULL | DQ5: NULL | DR5: ⊕0% APR for 24, 36, 40 or 48 Months with Equal Payments: Available on purchases of select products charged to a Samsung Financing account. Minimum purchase: $50. 0% APR from date of eligible purchase until paid in full. Estimated monthly payment equals the eligible purchase amount multiplied by a repayment factor and rounded to the nearest penny (repayment factors: .04167 for 24 month, .02778 for 36 month, .02500 for 40 month, .02083 for 48 month). Last payment may vary due to rounding. Total amount of payments will not exceed eligible purchase amount. Other transactions and fees affect overall minimum payment amount. Advertised payment amount is an estimate and may change once taxes, delivery or other charges are added. Limited time offer. Regular account terms apply to non-promo purchases. Minimum interest charge: $1. Standard Purchase APR: 29.99%. Prior purchases excluded. Account must be in good standing. Subject to credit approval. Samsung Financing account issued by TD Bank, N.A. | DS5: NULL | DT5: 0 | DU5: 0 | DV5: NULL | DW5: NULL | DX5: NULL | DY5: TC3 | DZ5: NULL | EA5: NULL | EB5: NULL | EC5: §18+ & 50 US/DC only. By 11/29/2020 11:59 PM EST, purchase a qualifying device on device installment plan, 2-year contract plan, lease or outright purchase at full retail price (“Qualifying Purchase”), & receive a Samsung Credit of $100 (“Gift”) instant credit from Samsung for use towards an eligible purchase including select wearables, tablets, PC’s and accessories when you purchase qualifying smartphone (“Qualifying Purchase”) before 01/15/21 at 11:59 PM EST. You must make a Qualifying Purchase on Samsung.com or the Shop Samsung App to receive an instant credit which may be applied instantly or deferred to a future eligible purchase. Gift valid for use on eligible purchases from 11/10/20- 01/15/21 or while supplies last, and is a one-time use certificate; when first used, any value not used is lost. Gift is non-transferrable and limited to 1 instant credit per registered customer. Samsung Credits are valid only at www.Samsung.com or in the App for use towards an eligible purchase. Void where prohibited or restricted by law. Additional restrictions apply. Offer subject to additional terms here. Samsung reserves the right to modify or discontinue offer at any time by posting notice on the app or website | ED5: NULL | EE5: https://www.samsung.com/us/ | EF5: 0 | EG5: NULL | EH5: NULL | EI5: NULL | EJ5: TC4 | EK5: NULL | EL5: NULL | EM5: NULL | EN5: †18+ & 50 US/DC only. By 11/29/2020 11:59 PM EST, purchase a qualifying device on device installment plan, 2-year contract plan, lease or outright purchase at full retail price (“Qualifying Purchase”), & receive a Samsung Credit of $30 (“Gift”) instant credit from Samsung for use towards an eligible purchase including select wearables, tablets, PC’s and accessories when you purchase qualifying smartphone (“Qualifying Purchase”) before 01/15/21 at 11:59 PM EST. You must make a Qualifying Purchase on Samsung.com or the Shop Samsung App to receive an instant credit which may be applied instantly or deferred to a future eligible purchase. Gift valid for use on eligible purchases from 11/10/20- 01/15/21 or while supplies last, and is a one-time use certificate; when first used, any value not used is lost. Gift is non-transferrable and limited to 1 instant credit per registered customer. Samsung Credits are valid only at www.Samsung.com or in the App for use towards an eligible purchase. Void where prohibited or restricted by law. Additional restrictions apply. Offer subject to additional terms here. Samsung reserves the right to modify or discontinue offer at any time by posting notice on the app or website | EO5: NULL | EP5: https://www.samsung.com/us/ | EQ5: 0 | ER5: NULL | ES5: NULL | ET5: NULL
