Workbook
Name __shared_10_0_0: #REF!
Name __shared_10_0_0: #REF!
Name __shared_10_0_0: #REF!
Name __shared_10_0_0: #REF!
Name __shared_10_0_1: #REF!
Name __shared_10_0_1: #REF!
Name __shared_10_0_1: #REF!
Name __shared_10_0_1: #REF!
Name __shared_10_0_10: #REF!
Name __shared_10_0_10: #REF!
Name __shared_10_0_10: #REF!
Name __shared_10_0_10: #REF!
Name __shared_10_0_11: #REF!
Name __shared_10_0_11: #REF!
Name __shared_10_0_11: #REF!
Name __shared_10_0_11: #REF!
Name __shared_10_0_12: "?siteid="&#REF!&"_"&#REF!&"_"&#REF!&"_"&#REF!&"_"&#REF!&"_"&#REF!
Name __shared_10_0_12: "?siteid="&#REF!&"_"&#REF!&"_"&#REF!&"_"&#REF!&"_"&#REF!&"_"&#REF!
Name __shared_10_0_12: "?siteid="&#REF!&"_"&#REF!&"_"&#REF!&"_"&#REF!&"_"&#REF!&"_"&#REF!
Name __shared_10_0_12: "?siteid="&#REF!&"_"&#REF!&"_"&#REF!&"_"&#REF!&"_"&#REF!&"_"&#REF!
Name __shared_10_0_13: #REF!
Name __shared_10_0_13: #REF!
Name __shared_10_0_13: #REF!
Name __shared_10_0_13: #REF!
Name __shared_10_0_14: #REF!
Name __shared_10_0_14: #REF!
Name __shared_10_0_14: #REF!
Name __shared_10_0_14: #REF!
Name __shared_10_0_15: #REF!
Name __shared_10_0_15: #REF!
Name __shared_10_0_15: #REF!
Name __shared_10_0_15: #REF!
Name __shared_10_0_16: "?siteid="&#REF!&"_"&#REF!&"_"&#REF!&"_"&#REF!&"_"&#REF!&"_"&#REF!
Name __shared_10_0_16: "?siteid="&#REF!&"_"&#REF!&"_"&#REF!&"_"&#REF!&"_"&#REF!&"_"&#REF!
Name __shared_10_0_16: "?siteid="&#REF!&"_"&#REF!&"_"&#REF!&"_"&#REF!&"_"&#REF!&"_"&#REF!
Name __shared_10_0_17: #REF!
Name __shared_10_0_17: #REF!
Name __shared_10_0_17: #REF!
Name __shared_10_0_17: #REF!
Name __shared_10_0_18: #REF!
Name __shared_10_0_18: #REF!
Name __shared_10_0_18: #REF!
Name __shared_10_0_18: #REF!
Name __shared_10_0_19: #REF!
Name __shared_10_0_19: #REF!
Name __shared_10_0_19: #REF!
Name __shared_10_0_19: #REF!
Name __shared_10_0_2: "?siteid="&#REF!&"_"&#REF!&"_"&#REF!&"_"&#REF!&"_"&#REF!&"_"&#REF!
Name __shared_10_0_2: "?siteid="&#REF!&"_"&#REF!&"_"&#REF!&"_"&#REF!&"_"&#REF!&"_"&#REF!
Name __shared_10_0_2: "?siteid="&#REF!&"_"&#REF!&"_"&#REF!&"_"&#REF!&"_"&#REF!&"_"&#REF!
Name __shared_10_0_20: #REF!
Name __shared_10_0_20: #REF!
Name __shared_10_0_20: #REF!
Name __shared_10_0_20: #REF!
Name __shared_10_0_21: #REF!
Name __shared_10_0_21: #REF!
Name __shared_10_0_21: #REF!
Name __shared_10_0_21: #REF!
Name __shared_10_0_22: TEXT(#REF!,"00")
Name __shared_10_0_22: TEXT(#REF!,"00")

Sheet Copy Deck Phase 1
A1: First | B1: Feature focused | C1: Lifestyle, Trade-in, Ecosystem, Compare | D1: Only feature Generic Compare chart AND trade-in chart across ALL versions
D2: Only versions 9-12 and 21-24. Only pricing in KV will change.
A3: Second | B3: Value focused | C3: Trade-in, Compare, Ecosystem, Lifestyle
A4: Third | B4: Instant Credit | C4: Ecosystem, Trade-in, Compare, Lifestyle
A5: Fourth | B5: Last minute | C5: KV 1, KV 2, Ecosystem, Trade-in, Compare
A7: Changes from T2 noted in green text & yellow fields.
A9: # | B9: Component | C9: Generic/N-1 | D9: N-2 $550 | E9: N-3 $350 | F9: N-4 $250/200 | G9: S10+ | H9: S10 | I9: S9+ | J9: N10+ | K9: S20+ | L9: S20 | M9: LO | N9: EPP Generic/N-1 | O9: EPP N-2 $550 | P9: EPP N-3 $350 | Q9: EPP N-4 $250/200 | R9: EPP S10+ | S9: EPP S10 | T9: EPP S9+ | U9: EPP N10+ | V9: EPP S20+ | W9: EPP S20 | X9: EPP LO | Y9: EPP Non-Reservers | Z9: Notes
B10: SL 1 | C10: [NAME], it's your last chance to pre-order Galaxy S21 5G and get up to $250 instant credit. | D10: [NAME], it's your last chance to pre-order Galaxy S21 5G and get up to $250 instant credit. | E10: [NAME], it's your last chance to pre-order Galaxy S21 5G and get up to $250 instant credit. | F10: [NAME], it's your last chance to pre-order Galaxy S21 5G and get up to $250 instant credit. | G10: [NAME], it's your last chance to pre-order Galaxy S21 5G and get up to $250 instant credit. | H10: [NAME], it's your last chance to pre-order Galaxy S21 5G and get up to $250 instant credit. | I10: [NAME], it's your last chance to pre-order Galaxy S21 5G and get up to $250 instant credit. | J10: [NAME], it's your last chance to pre-order Galaxy S21 5G and get up to $250 instant credit. | K10: [NAME], it's your last chance to pre-order Galaxy S21 5G and get up to $250 instant credit. | L10: [NAME], it's your last chance to pre-order Galaxy S21 5G and get up to $250 instant credit. | M10: [NAME], it's your last chance to pre-order Galaxy S21 5G and get up to $250 instant credit. | N10: [NAME], it's your last chance to pre-order Galaxy S21 5G and get up to $250 instant credit. | O10: [NAME], it's your last chance to pre-order Galaxy S21 5G and get up to $250 instant credit. | P10: [NAME], it's your last chance to pre-order Galaxy S21 5G and get up to $250 instant credit. | Q10: [NAME], it's your last chance to pre-order Galaxy S21 5G and get up to $250 instant credit. | R10: [NAME], it's your last chance to pre-order Galaxy S21 5G and get up to $250 instant credit. | S10: [NAME], it's your last chance to pre-order Galaxy S21 5G and get up to $250 instant credit. | T10: [NAME], it's your last chance to pre-order Galaxy S21 5G and get up to $250 instant credit. | U10: [NAME], it's your last chance to pre-order Galaxy S21 5G and get up to $250 instant credit. | V10: [NAME], it's your last chance to pre-order Galaxy S21 5G and get up to $250 instant credit. | W10: [NAME], it's your last chance to pre-order Galaxy S21 5G and get up to $250 instant credit. | X10: [NAME], it's your last chance to pre-order Galaxy S21 5G and get up to $250 instant credit. | Y10: [NAME], it's your last chance to pre-order Galaxy S21 5G and get up to $200 instant credit.
B11: PH 2 | C11: Plus, don't miss out on exclusive bundle offers and up to $700 enhanced trade-in credit. | D11: Plus, don't miss out on exclusive bundle offers and up to $550 enhanced trade-in credit. | E11: Plus, don't miss out on exclusive bundle offers and up to $350 enhanced trade-in credit. | F11: Plus, don't miss out on exclusive bundle offers and up to $250 enhanced trade-in credit. | G11: Plus, don't miss out on exclusive bundle offers and up to $550 enhanced trade-in credit. | H11: Plus, don't miss out on exclusive bundle offers and up to $550 enhanced trade-in credit. | I11: Plus, don't miss out on exclusive bundle offers and up to $350 enhanced trade-in credit. | J11: Plus, don't miss out on exclusive bundle offers and up to $550 enhanced trade-in credit. | K11: Plus, don't miss out on exclusive bundle offers and up to $700 enhanced trade-in credit. | L11: Plus, don't miss out on exclusive bundle offers and up to $700 enhanced trade-in credit. | M11: Plus, don't miss out on exclusive bundle offers and up to $700 enhanced trade-in credit. | N11: Plus, don't miss out on exclusive bundle offers and up to $700 enhanced trade-in credit. | O11: Plus, don't miss out on exclusive bundle offers and up to $550 enhanced trade-in credit. | P11: Plus, don't miss out on exclusive bundle offers and up to $350 enhanced trade-in credit. | Q11: Plus, don't miss out on exclusive bundle offers and up to $250 enhanced trade-in credit. | R11: Plus, don't miss out on exclusive bundle offers and up to $550 enhanced trade-in credit. | S11: Plus, don't miss out on exclusive bundle offers and up to $550 enhanced trade-in credit. | T11: Plus, don't miss out on exclusive bundle offers and up to $350 enhanced trade-in credit. | U11: Plus, don't miss out on exclusive bundle offers and up to $550 enhanced trade-in credit. | V11: Plus, don't miss out on exclusive bundle offers and up to $700 enhanced trade-in credit. | W11: Plus, don't miss out on exclusive bundle offers and up to $700 enhanced trade-in credit. | X11: Plus, don't miss out on exclusive bundle offers and up to $700 enhanced trade-in credit. | Y11: Plus, don't miss out on exclusive bundle offers and up to $700 enhanced trade-in credit.
B12: EYEBROW | C12: <Samsung logo> | D12: <Samsung logo> | E12: <Samsung logo> | F12: <Samsung logo> | G12: <Samsung logo> | H12: <Samsung logo> | I12: <Samsung logo> | J12: <Samsung logo> | K12: <Samsung logo> | L12: <Samsung logo> | M12: <Samsung logo> | N12: <Samsung logo> | O12: <Samsung logo> | P12: <Samsung logo> | Q12: <Samsung logo> | R12: <Samsung logo> | S12: <Samsung logo> | T12: <Samsung logo> | U12: <Samsung logo> | V12: <Samsung logo> | W12: <Samsung logo> | X12: <Samsung logo> | Y12: <Samsung logo>
B13: HERO HL 1 | C13: NULL | D13: NULL | E13: NULL | F13: NULL | G13: NULL | H13: NULL | I13: NULL | J13: NULL | K13: NULL | L13: NULL | M13: NULL | N13: <EPP Banner audience list> | O13: <EPP Banner audience list> | P13: <EPP Banner audience list> | Q13: <EPP Banner audience list> | R13: <EPP Banner audience list> | S13: <EPP Banner audience list> | T13: <EPP Banner audience list> | U13: <EPP Banner audience list> | V13: <EPP Banner audience list> | W13: <EPP Banner audience list> | X13: <EPP Banner audience list> | Y13: <EPP Banner audience list>
B14: HERO SH 1 | C14: <countdown timer> Time is running out to pre-order Galaxy S21 5G and get: • Up to $250 instant credit, which includes your exclusive $50 credit1 • Up to $700 enhanced trade-in creditᶿ • A free Galaxy SmartTag1 | D14: <countdown timer> Time is running out to pre-order Galaxy S21 5G and get: • Up to $250 instant credit, which includes your exclusive $50 credit1 • Up to $550 enhanced trade-in creditᶿ • A free Galaxy SmartTag1 | E14: <countdown timer> Time is running out to pre-order Galaxy S21 5G and get: • Up to $250 instant credit, which includes your exclusive $50 credit1 • Up to $350 enhanced trade-in creditᶿ • A free Galaxy SmartTag1 | F14: <countdown timer> Time is running out to pre-order Galaxy S21 5G and get: • Up to $250 instant credit, which includes your exclusive $50 credit1 • Up to $250 enhanced trade-in creditᶿ • A free Galaxy SmartTag1 | G14: <countdown timer> Time is running out to pre-order Galaxy S21 5G and get: • Up to $250 instant credit, which includes your exclusive $50 credit1 • Up to $550 enhanced trade-in creditᶿ • A free Galaxy SmartTag1 | H14: <countdown timer> Time is running out to pre-order Galaxy S21 5G and get: • Up to $250 instant credit, which includes your exclusive $50 credit1 • Up to $550 enhanced trade-in creditᶿ • A free Galaxy SmartTag1 | I14: <countdown timer> Time is running out to pre-order Galaxy S21 5G and get: • Up to $250 instant credit, which includes your exclusive $50 credit1 • Up to $350 enhanced trade-in creditᶿ • A free Galaxy SmartTag1 | J14: <countdown timer> Time is running out to pre-order Galaxy S21 5G and get: • Up to $250 instant credit, which includes your exclusive $50 credit1 • Up to $550 enhanced trade-in creditᶿ • A free Galaxy SmartTag1 | K14: <countdown timer> Time is running out to pre-order Galaxy S21 5G and get: • Up to $250 instant credit, which includes your exclusive $50 credit1 • Up to $700 enhanced trade-in creditᶿ • A free Galaxy SmartTag1 | L14: <countdown timer> Time is running out to pre-order Galaxy S21 5G and get: • Up to $250 instant credit, which includes your exclusive $50 credit1 • Up to $700 enhanced trade-in creditᶿ • A free Galaxy SmartTag1 | M14: <countdown timer> Time is running out to pre-order Galaxy S21 5G and get: • Up to $250 instant credit, which includes your exclusive $50 credit1 • Up to $700 enhanced trade-in creditᶿ • A free Galaxy SmartTag1 | N14: Login to your Samsung Discount Program account to access your exclusive pricing below. | O14: Login to your Samsung Discount Program account to access your exclusive pricing below. | P14: Login to your Samsung Discount Program account to access your exclusive pricing below. | Q14: Login to your Samsung Discount Program account to access your exclusive pricing below. | R14: Login to your Samsung Discount Program account to access your exclusive pricing below. | S14: Login to your Samsung Discount Program account to access your exclusive pricing below. | T14: Login to your Samsung Discount Program account to access your exclusive pricing below. | U14: Login to your Samsung Discount Program account to access your exclusive pricing below. | V14: Login to your Samsung Discount Program account to access your exclusive pricing below. | W14: Login to your Samsung Discount Program account to access your exclusive pricing below. | X14: Login to your Samsung Discount Program account to access your exclusive pricing below. | Y14: Login to your Samsung Discount Program account to access your exclusive pricing below.
B15: HERO SC 1 | C15: NULL | D15: NULL | E15: NULL | F15: NULL | G15: NULL | H15: NULL | I15: NULL | J15: NULL | K15: NULL | L15: NULL | M15: NULL | N15: <countdown timer> Time is running out to pre-order Galaxy S21 5G and get: • Up to $250 instant credit, which includes your exclusive $50 credit1 • Up to $700 enhanced trade-in creditᶿ • A free Galaxy SmartTag1 | O15: <countdown timer> Time is running out to pre-order Galaxy S21 5G and get: • Up to $250 instant credit, which includes your exclusive $50 credit1 • Up to $550 enhanced trade-in creditᶿ • A free Galaxy SmartTag1 | P15: <countdown timer> Time is running out to pre-order Galaxy S21 5G and get: • Up to $250 instant credit, which includes your exclusive $50 credit1 • Up to $350 enhanced trade-in creditᶿ • A free Galaxy SmartTag1 | Q15: <countdown timer> Time is running out to pre-order Galaxy S21 5G and get: • Up to $250 instant credit, which includes your exclusive $50 credit1 • Up to $250 enhanced trade-in creditᶿ • A free Galaxy SmartTag1 | R15: <countdown timer> Time is running out to pre-order Galaxy S21 5G and get: • Up to $250 instant credit, which includes your exclusive $50 credit1 • Up to $550 enhanced trade-in creditᶿ • A free Galaxy SmartTag1 | S15: <countdown timer> Time is running out to pre-order Galaxy S21 5G and get: • Up to $250 instant credit, which includes your exclusive $50 credit1 • Up to $550 enhanced trade-in creditᶿ • A free Galaxy SmartTag1 | T15: <countdown timer> Time is running out to pre-order Galaxy S21 5G and get: • Up to $250 instant credit, which includes your exclusive $50 credit1 • Up to $350 enhanced trade-in creditᶿ • A free Galaxy SmartTag1 | U15: <countdown timer> Time is running out to pre-order Galaxy S21 5G and get: • Up to $250 instant credit, which includes your exclusive $50 credit1 • Up to $550 enhanced trade-in creditᶿ • A free Galaxy SmartTag1 | V15: <countdown timer> Time is running out to pre-order Galaxy S21 5G and get: • Up to $250 instant credit, which includes your exclusive $50 credit1 • Up to $700 enhanced trade-in creditᶿ • A free Galaxy SmartTag1 | W15: <countdown timer> Time is running out to pre-order Galaxy S21 5G and get: • Up to $250 instant credit, which includes your exclusive $50 credit1 • Up to $700 enhanced trade-in creditᶿ • A free Galaxy SmartTag1 | X15: <countdown timer> Time is running out to pre-order Galaxy S21 5G and get: • Up to $250 instant credit, which includes your exclusive $50 credit1 • Up to $700 enhanced trade-in creditᶿ • A free Galaxy SmartTag1 | Y15: <countdown timer> Time is running out to pre-order Galaxy S21 5G and get: • Up to $200 instant credit, which includes your exclusive $50 credit1 • Up to $700 enhanced trade-in creditᶿ • A free Galaxy SmartTag1
A16: 1 | B16: KV 1 HL | C16: Galaxy S21 Ultra 5G | D16: Galaxy S21 Ultra 5G | E16: Galaxy S21 Ultra 5G | F16: Galaxy S21 Ultra 5G | G16: Galaxy S21 Ultra 5G | H16: Galaxy S21 Ultra 5G | I16: Galaxy S21 Ultra 5G | J16: Galaxy S21 Ultra 5G | K16: Galaxy S21 Ultra 5G | L16: Galaxy S21 Ultra 5G | M16: Galaxy S21 Ultra 5G | N16: Galaxy S21 Ultra 5G | O16: Galaxy S21 Ultra 5G | P16: Galaxy S21 Ultra 5G | Q16: Galaxy S21 Ultra 5G | R16: Galaxy S21 Ultra 5G | S16: Galaxy S21 Ultra 5G | T16: Galaxy S21 Ultra 5G | U16: Galaxy S21 Ultra 5G | V16: Galaxy S21 Ultra 5G | W16: Galaxy S21 Ultra 5G | X16: Galaxy S21 Ultra 5G | Y16: Galaxy S21 Ultra 5G
B17: KV 1 SH | C17: Welcome to the Everyday Epic | D17: Welcome to the Everyday Epic | E17: Welcome to the Everyday Epic | F17: Welcome to the Everyday Epic | G17: Welcome to the Everyday Epic | H17: Welcome to the Everyday Epic | I17: Welcome to the Everyday Epic | J17: Welcome to the Everyday Epic | K17: Welcome to the Everyday Epic | L17: Welcome to the Everyday Epic | M17: Welcome to the Everyday Epic | N17: Welcome to the Everyday Epic | O17: Welcome to the Everyday Epic | P17: Welcome to the Everyday Epic | Q17: Welcome to the Everyday Epic | R17: Welcome to the Everyday Epic | S17: Welcome to the Everyday Epic | T17: Welcome to the Everyday Epic | U17: Welcome to the Everyday Epic | V17: Welcome to the Everyday Epic | W17: Welcome to the Everyday Epic | X17: Welcome to the Everyday Epic | Y17: Welcome to the Everyday Epic
B18: KV 1 SC | C18: From $499.99 with eligible trade-in.ᶿ Plus, get $250 instant credit to complete your Galaxy Ecosystem.1 | D18: From $649.99 with eligible trade-in.ᶿ Plus, get $250 instant credit to complete your Galaxy Ecosystem.1 | E18: From $849.99 with eligible trade-in.ᶿ Plus, get $250 instant credit to complete your Galaxy Ecosystem.1 | F18: From $949.99 with eligible trade-in.ᶿ Plus, get $250 instant credit to complete your Galaxy Ecosystem.1 | G18: From $649.99 with eligible trade-in.ᶿ Plus, get $250 instant credit to complete your Galaxy Ecosystem.1 | H18: From $649.99 with eligible trade-in.ᶿ Plus, get $250 instant credit to complete your Galaxy Ecosystem.1 | I18: From $849.99 with eligible trade-in.ᶿ Plus, get $250 instant credit to complete your Galaxy Ecosystem.1 | J18: From $649.99 with eligible trade-in.ᶿ Plus, get $250 instant credit to complete your Galaxy Ecosystem.1 | K18: From $499.99 with eligible trade-in.ᶿ Plus, get $250 instant credit to complete your Galaxy Ecosystem.1 | L18: From $499.99 with eligible trade-in.ᶿ Plus, get $250 instant credit to complete your Galaxy Ecosystem.1 | M18: From $499.99 with eligible trade-in.ᶿ Plus, get $250 instant credit to complete your Galaxy Ecosystem.1 | N18: From $474.99 with eligible trade-in.ᶿ Plus, get $250 instant credit to complete your Galaxy Ecosystem.1 | O18: From $617.49 with eligible trade-in.ᶿ Plus, get $250 instant credit to complete your Galaxy Ecosystem.1 | P18: From $807.49 with eligible trade-in.ᶿ Plus, get $250 instant credit to complete your Galaxy Ecosystem.1 | Q18: From $902.49 with eligible trade-in.ᶿ Plus, get $250 instant credit to complete your Galaxy Ecosystem.1 | R18: From $617.49 with eligible trade-in.ᶿ Plus, get $250 instant credit to complete your Galaxy Ecosystem.1 | S18: From $617.49 with eligible trade-in.ᶿ Plus, get $250 instant credit to complete your Galaxy Ecosystem.1 | T18: From $807.49 with eligible trade-in.ᶿ Plus, get $250 instant credit to complete your Galaxy Ecosystem.1 | U18: From $617.49 with eligible trade-in.ᶿ Plus, get $250 instant credit to complete your Galaxy Ecosystem.1 | V18: From $474.99 with eligible trade-in.ᶿ Plus, get $250 instant credit to complete your Galaxy Ecosystem.1 | W18: From $474.99 with eligible trade-in.ᶿ Plus, get $250 instant credit to complete your Galaxy Ecosystem.1 | X18: From $474.99 with eligible trade-in.ᶿ Plus, get $250 instant credit to complete your Galaxy Ecosystem.1 | Y18: From $474.99 with eligible trade-in.ᶿ Plus, get $200 instant credit to complete your Galaxy Ecosystem.1
B19: KV 1 CTA | C19: Pre-order Galaxy S21 Ultra 5G | D19: Pre-order Galaxy S21 Ultra 5G | E19: Pre-order Galaxy S21 Ultra 5G | F19: Pre-order Galaxy S21 Ultra 5G | G19: Pre-order Galaxy S21 Ultra 5G | H19: Pre-order Galaxy S21 Ultra 5G | I19: Pre-order Galaxy S21 Ultra 5G | J19: Pre-order Galaxy S21 Ultra 5G | K19: Pre-order Galaxy S21 Ultra 5G | L19: Pre-order Galaxy S21 Ultra 5G | M19: Pre-order Galaxy S21 Ultra 5G | N19: Pre-order Galaxy S21 Ultra 5G | O19: Pre-order Galaxy S21 Ultra 5G | P19: Pre-order Galaxy S21 Ultra 5G | Q19: Pre-order Galaxy S21 Ultra 5G | R19: Pre-order Galaxy S21 Ultra 5G | S19: Pre-order Galaxy S21 Ultra 5G | T19: Pre-order Galaxy S21 Ultra 5G | U19: Pre-order Galaxy S21 Ultra 5G | V19: Pre-order Galaxy S21 Ultra 5G | W19: Pre-order Galaxy S21 Ultra 5G | X19: Pre-order Galaxy S21 Ultra 5G | Y19: Pre-order Galaxy S21 Ultra 5G
B20: KV 1 CTA Disclaimer | C20: Click "Pre-order Galaxy S21 Ultra 5G" to redeem your instant credit. | D20: Click "Pre-order Galaxy S21 Ultra 5G" to redeem your instant credit. | E20: Click "Pre-order Galaxy S21 Ultra 5G" to redeem your instant credit. | F20: Click "Pre-order Galaxy S21 Ultra 5G" to redeem your instant credit. | G20: Click "Pre-order Galaxy S21 Ultra 5G" to redeem your instant credit. | H20: Click "Pre-order Galaxy S21 Ultra 5G" to redeem your instant credit. | I20: Click "Pre-order Galaxy S21 Ultra 5G" to redeem your instant credit. | J20: Click "Pre-order Galaxy S21 Ultra 5G" to redeem your instant credit. | K20: Click "Pre-order Galaxy S21 Ultra 5G" to redeem your instant credit. | L20: Click "Pre-order Galaxy S21 Ultra 5G" to redeem your instant credit. | M20: Click "Pre-order Galaxy S21 Ultra 5G" to redeem your instant credit. | N20: Click "Pre-order Galaxy S21 Ultra 5G" to redeem your instant credit. | O20: Click "Pre-order Galaxy S21 Ultra 5G" to redeem your instant credit. | P20: Click "Pre-order Galaxy S21 Ultra 5G" to redeem your instant credit. | Q20: Click "Pre-order Galaxy S21 Ultra 5G" to redeem your instant credit. | R20: Click "Pre-order Galaxy S21 Ultra 5G" to redeem your instant credit. | S20: Click "Pre-order Galaxy S21 Ultra 5G" to redeem your instant credit. | T20: Click "Pre-order Galaxy S21 Ultra 5G" to redeem your instant credit. | U20: Click "Pre-order Galaxy S21 Ultra 5G" to redeem your instant credit. | V20: Click "Pre-order Galaxy S21 Ultra 5G" to redeem your instant credit. | W20: Click "Pre-order Galaxy S21 Ultra 5G" to redeem your instant credit. | X20: Click "Pre-order Galaxy S21 Ultra 5G" to redeem your instant credit. | Y20: Click "Pre-order Galaxy S21 Ultra 5G" to redeem your instant credit.
B21: KV 1 Image | C21: <Galaxy S21 Ultra 5G> | D21: <Galaxy S21 Ultra 5G> | E21: <Galaxy S21 Ultra 5G> | F21: <Galaxy S21 Ultra 5G> | G21: <Galaxy S21 Ultra 5G> | H21: <Galaxy S21 Ultra 5G> | I21: <Galaxy S21 Ultra 5G> | J21: <Galaxy S21 Ultra 5G> | K21: <Galaxy S21 Ultra 5G> | L21: <Galaxy S21 Ultra 5G> | M21: <Galaxy S21 Ultra 5G> | N21: <Galaxy S21 Ultra 5G> | O21: <Galaxy S21 Ultra 5G> | P21: <Galaxy S21 Ultra 5G> | Q21: <Galaxy S21 Ultra 5G> | R21: <Galaxy S21 Ultra 5G> | S21: <Galaxy S21 Ultra 5G> | T21: <Galaxy S21 Ultra 5G> | U21: <Galaxy S21 Ultra 5G> | V21: <Galaxy S21 Ultra 5G> | W21: <Galaxy S21 Ultra 5G> | X21: <Galaxy S21 Ultra 5G> | Y21: <Galaxy S21 Ultra 5G>
B22: KV 1 Disclaimer | C22: NULL | D22: NULL | E22: NULL | F22: NULL | G22: NULL | H22: NULL | I22: NULL | J22: NULL | K22: NULL | L22: NULL | M22: NULL | N22: NULL | O22: NULL | P22: NULL | Q22: NULL | R22: NULL | S22: NULL | T22: NULL | U22: NULL | V22: NULL | W22: NULL | X22: NULL | Y22: NULL
A23: 2 | B23: KV 2 HL | C23: Galaxy S21 5G I S21+ 5G | D23: Galaxy S21 5G I S21+ 5G | E23: Galaxy S21 5G I S21+ 5G | F23: Galaxy S21 5G I S21+ 5G | G23: Galaxy S21 5G I S21+ 5G | H23: Galaxy S21 5G I S21+ 5G | I23: Galaxy S21 5G I S21+ 5G | J23: Galaxy S21 5G I S21+ 5G | K23: Galaxy S21 5G I S21+ 5G | L23: Galaxy S21 5G I S21+ 5G | M23: Galaxy S21 5G I S21+ 5G | N23: Galaxy S21 5G I S21+ 5G | O23: Galaxy S21 5G I S21+ 5G | P23: Galaxy S21 5G I S21+ 5G | Q23: Galaxy S21 5G I S21+ 5G | R23: Galaxy S21 5G I S21+ 5G | S23: Galaxy S21 5G I S21+ 5G | T23: Galaxy S21 5G I S21+ 5G | U23: Galaxy S21 5G I S21+ 5G | V23: Galaxy S21 5G I S21+ 5G | W23: Galaxy S21 5G I S21+ 5G | X23: Galaxy S21 5G I S21+ 5G | Y23: Galaxy S21 5G I S21+ 5G
B24: KV 2 SH | C24: NULL | D24: NULL | E24: NULL | F24: NULL | G24: NULL | H24: NULL | I24: NULL | J24: NULL | K24: NULL | L24: NULL | M24: NULL | N24: NULL | O24: NULL | P24: NULL | Q24: NULL | R24: NULL | S24: NULL | T24: NULL | U24: NULL | V24: NULL | W24: NULL | X24: NULL | Y24: NULL
B25: KV 2 SC | C25: From $99.99 with eligible trade-in.ᶿ Plus, get $150 or more instant credit to complete your Galaxy Ecosystem.1 | D25: From $249.99 with eligible trade-in.ᶿ Plus, get $150 or more instant credit to complete your Galaxy Ecosystem.1 | E25: From $449.99 with eligible trade-in.ᶿ Plus, get $150 or more instant credit to complete your Galaxy Ecosystem.1 | F25: From $549.99 with eligible trade-in.ᶿ Plus, get $150 or more instant credit to complete your Galaxy Ecosystem.1 | G25: From $249.99 with eligible trade-in.ᶿ Plus, get $150 or more instant credit to complete your Galaxy Ecosystem.1 | H25: From $249.99 with eligible trade-in.ᶿ Plus, get $150 or more instant credit to complete your Galaxy Ecosystem.1 | I25: From $449.99 with eligible trade-in.ᶿ Plus, get $150 or more instant credit to complete your Galaxy Ecosystem.1 | J25: From $249.99 with eligible trade-in.ᶿ Plus, get $150 or more instant credit to complete your Galaxy Ecosystem.1 | K25: From $99.99 with eligible trade-in.ᶿ Plus, get $150 or more instant credit to complete your Galaxy Ecosystem.1 | L25: From $99.99 with eligible trade-in.ᶿ Plus, get $150 or more instant credit to complete your Galaxy Ecosystem.1 | M25: From $99.99 with eligible trade-in.ᶿ Plus, get $150 or more instant credit to complete your Galaxy Ecosystem.1 | N25: From $94.99 with eligible trade-in.ᶿ Plus, get $150 or more instant credit to complete your Galaxy Ecosystem.1 | O25: From $237.49 with eligible trade-in.ᶿ Plus, get $150 or more instant credit to complete your Galaxy Ecosystem.1 | P25: From $427.49 with eligible trade-in.ᶿ Plus, get $150 or more instant credit to complete your Galaxy Ecosystem.1 | Q25: From $522.49 with eligible trade-in.ᶿ Plus, get up to $200 instant credit to complete your Galaxy Ecosystem.1 | R25: From $237.49 with eligible trade-in.ᶿ Plus, get $150 or more instant credit to complete your Galaxy Ecosystem.1 | S25: From $237.49 with eligible trade-in.ᶿ Plus, get $150 or more instant credit to complete your Galaxy Ecosystem.1 | T25: From $427.49 with eligible trade-in.ᶿ Plus, get $150 or more instant credit to complete your Galaxy Ecosystem.1 | U25: From $237.49 with eligible trade-in.ᶿ Plus, get $150 or more instant credit to complete your Galaxy Ecosystem.1 | V25: From $94.99 with eligible trade-in.ᶿ Plus, get $150 or more instant credit to complete your Galaxy Ecosystem.1 | W25: From $94.99 with eligible trade-in.ᶿ Plus, get $150 or more instant credit to complete your Galaxy Ecosystem.1 | X25: From $94.99 with eligible trade-in.ᶿ Plus, get $150 or more instant credit to complete your Galaxy Ecosystem.1 | Y25: From $94.99 with eligible trade-in.ᶿ Plus, get $100 or more instant credit to complete your Galaxy Ecosystem.1
B26: KV CTA | C26: Pre-order Galaxy S21 5G or S21+ 5G | D26: Pre-order Galaxy S21 5G or S21+ 5G | E26: Pre-order Galaxy S21 5G or S21+ 5G | F26: Pre-order Galaxy S21 5G or S21+ 5G | G26: Pre-order Galaxy S21 5G or S21+ 5G | H26: Pre-order Galaxy S21 5G or S21+ 5G | I26: Pre-order Galaxy S21 5G or S21+ 5G | J26: Pre-order Galaxy S21 5G or S21+ 5G | K26: Pre-order Galaxy S21 5G or S21+ 5G | L26: Pre-order Galaxy S21 5G or S21+ 5G | M26: Pre-order Galaxy S21 5G or S21+ 5G | N26: Pre-order Galaxy S21 5G or S21+ 5G | O26: Pre-order Galaxy S21 5G or S21+ 5G | P26: Pre-order Galaxy S21 5G or S21+ 5G | Q26: Pre-order Galaxy S21 5G or S21+ 5G | R26: Pre-order Galaxy S21 5G or S21+ 5G | S26: Pre-order Galaxy S21 5G or S21+ 5G | T26: Pre-order Galaxy S21 5G or S21+ 5G | U26: Pre-order Galaxy S21 5G or S21+ 5G | V26: Pre-order Galaxy S21 5G or S21+ 5G | W26: Pre-order Galaxy S21 5G or S21+ 5G | X26: Pre-order Galaxy S21 5G or S21+ 5G | Y26: Pre-order Galaxy S21 5G or S21+ 5G
B27: KV CTA Disclaimer | C27: Click "Pre-order Galaxy S21 5G or S21+ 5G" to redeem your instant credit. | D27: Click "Pre-order Galaxy S21 5G or S21+ 5G" to redeem your instant credit. | E27: Click "Pre-order Galaxy S21 5G or S21+ 5G" to redeem your instant credit. | F27: Click "Pre-order Galaxy S21 5G or S21+ 5G" to redeem your instant credit. | G27: Click "Pre-order Galaxy S21 5G or S21+ 5G" to redeem your instant credit. | H27: Click "Pre-order Galaxy S21 5G or S21+ 5G" to redeem your instant credit. | I27: Click "Pre-order Galaxy S21 5G or S21+ 5G" to redeem your instant credit. | J27: Click "Pre-order Galaxy S21 5G or S21+ 5G" to redeem your instant credit. | K27: Click "Pre-order Galaxy S21 5G or S21+ 5G" to redeem your instant credit. | L27: Click "Pre-order Galaxy S21 5G or S21+ 5G" to redeem your instant credit. | M27: Click "Pre-order Galaxy S21 5G or S21+ 5G" to redeem your instant credit. | N27: Click "Pre-order Galaxy S21 5G or S21+ 5G" to redeem your instant credit. | O27: Click "Pre-order Galaxy S21 5G or S21+ 5G" to redeem your instant credit. | P27: Click "Pre-order Galaxy S21 5G or S21+ 5G" to redeem your instant credit. | Q27: Click "Pre-order Galaxy S21 5G or S21+ 5G" to redeem your instant credit. | R27: Click "Pre-order Galaxy S21 5G or S21+ 5G" to redeem your instant credit. | S27: Click "Pre-order Galaxy S21 5G or S21+ 5G" to redeem your instant credit. | T27: Click "Pre-order Galaxy S21 5G or S21+ 5G" to redeem your instant credit. | U27: Click "Pre-order Galaxy S21 5G or S21+ 5G" to redeem your instant credit. | V27: Click "Pre-order Galaxy S21 5G or S21+ 5G" to redeem your instant credit. | W27: Click "Pre-order Galaxy S21 5G or S21+ 5G" to redeem your instant credit. | X27: Click "Pre-order Galaxy S21 5G or S21+ 5G" to redeem your instant credit. | Y27: Click "Pre-order Galaxy S21 5G or S21+ 5G" to redeem your instant credit.
B28: KV Image | C28: <Galaxy S21 5G, Galaxy S21+ 5G> | D28: <Galaxy S21 5G, Galaxy S21+ 5G> | E28: <Galaxy S21 5G, Galaxy S21+ 5G> | F28: <Galaxy S21 5G, Galaxy S21+ 5G> | G28: <Galaxy S21 5G, Galaxy S21+ 5G> | H28: <Galaxy S21 5G, Galaxy S21+ 5G> | I28: <Galaxy S21 5G, Galaxy S21+ 5G> | J28: <Galaxy S21 5G, Galaxy S21+ 5G> | K28: <Galaxy S21 5G, Galaxy S21+ 5G> | L28: <Galaxy S21 5G, Galaxy S21+ 5G> | M28: <Galaxy S21 5G, Galaxy S21+ 5G> | N28: <Galaxy S21 5G, Galaxy S21+ 5G> | O28: <Galaxy S21 5G, Galaxy S21+ 5G> | P28: <Galaxy S21 5G, Galaxy S21+ 5G> | Q28: <Galaxy S21 5G, Galaxy S21+ 5G> | R28: <Galaxy S21 5G, Galaxy S21+ 5G> | S28: <Galaxy S21 5G, Galaxy S21+ 5G> | T28: <Galaxy S21 5G, Galaxy S21+ 5G> | U28: <Galaxy S21 5G, Galaxy S21+ 5G> | V28: <Galaxy S21 5G, Galaxy S21+ 5G> | W28: <Galaxy S21 5G, Galaxy S21+ 5G> | X28: <Galaxy S21 5G, Galaxy S21+ 5G> | Y28: <Galaxy S21 5G, Galaxy S21+ 5G>
B29: KV Disclaimer | C29: NULL | D29: NULL | E29: NULL | F29: NULL | G29: NULL | H29: NULL | I29: NULL | J29: NULL | K29: NULL | L29: NULL | M29: NULL | N29: NULL | O29: NULL | P29: NULL | Q29: NULL | R29: NULL | S29: NULL | T29: NULL | U29: NULL | V29: NULL | W29: NULL | X29: NULL | Y29: NULL
A30: 3 | B30: Ecosystem HL | C30: Complete your Galaxy Ecosystem with up to $250 instant credit1 | D30: Complete your Galaxy Ecosystem with up to $250 instant credit1 | E30: Complete your Galaxy Ecosystem with up to $250 instant credit1 | F30: Complete your Galaxy Ecosystem with up to $250 instant credit1 | G30: Complete your Galaxy Ecosystem with up to $250 instant credit1 | H30: Complete your Galaxy Ecosystem with up to $250 instant credit1 | I30: Complete your Galaxy Ecosystem with up to $250 instant credit1 | J30: Complete your Galaxy Ecosystem with up to $250 instant credit1 | K30: Complete your Galaxy Ecosystem with up to $250 instant credit1 | L30: Complete your Galaxy Ecosystem with up to $250 instant credit1 | M30: Complete your Galaxy Ecosystem with up to $250 instant credit1 | N30: Complete your Galaxy Ecosystem with up to $250 instant credit1 | O30: Complete your Galaxy Ecosystem with up to $250 instant credit1 | P30: Complete your Galaxy Ecosystem with up to $250 instant credit1 | Q30: Complete your Galaxy Ecosystem with up to $250 instant credit1 | R30: Complete your Galaxy Ecosystem with up to $250 instant credit1 | S30: Complete your Galaxy Ecosystem with up to $250 instant credit1 | T30: Complete your Galaxy Ecosystem with up to $250 instant credit1 | U30: Complete your Galaxy Ecosystem with up to $250 instant credit1 | V30: Complete your Galaxy Ecosystem with up to $250 instant credit1 | W30: Complete your Galaxy Ecosystem with up to $250 instant credit1 | X30: Complete your Galaxy Ecosystem with up to $250 instant credit1 | Y30: Complete your Galaxy Ecosystem with up to $200 instant credit1
B31: Ecosystem KV | C31: <Ecosystem image> | D31: <Ecosystem image> | E31: <Ecosystem image> | F31: <Ecosystem image> | G31: <Ecosystem image> | H31: <Ecosystem image> | I31: <Ecosystem image> | J31: <Ecosystem image> | K31: <Ecosystem image> | L31: <Ecosystem image> | M31: <Ecosystem image> | N31: <Ecosystem image> | O31: <Ecosystem image> | P31: <Ecosystem image> | Q31: <Ecosystem image> | R31: <Ecosystem image> | S31: <Ecosystem image> | T31: <Ecosystem image> | U31: <Ecosystem image> | V31: <Ecosystem image> | W31: <Ecosystem image> | X31: <Ecosystem image> | Y31: <Ecosystem image>
B32: Ecosystem SH | C32: NULL | D32: NULL | E32: NULL | F32: NULL | G32: NULL | H32: NULL | I32: NULL | J32: NULL | K32: NULL | L32: NULL | M32: NULL | N32: NULL | O32: NULL | P32: NULL | Q32: NULL | R32: NULL | S32: NULL | T32: NULL | U32: NULL | V32: NULL | W32: NULL | X32: NULL | Y32: NULL
B33: Table Line 1 | C33: Pre-order now and redeem up to $250 instant credit1 toward the offers below or toward other eligible, must-have devices. | D33: Pre-order now and redeem up to $250 instant credit1 toward the offers below or toward other eligible, must-have devices. | E33: Pre-order now and redeem up to $250 instant credit1 toward the offers below or toward other eligible, must-have devices. | F33: Pre-order now and redeem up to $250 instant credit1 toward the offers below or toward other eligible, must-have devices. | G33: Pre-order now and redeem up to $250 instant credit1 toward the offers below or toward other eligible, must-have devices. | H33: Pre-order now and redeem up to $250 instant credit1 toward the offers below or toward other eligible, must-have devices. | I33: Pre-order now and redeem up to $250 instant credit1 toward the offers below or toward other eligible, must-have devices. | J33: Pre-order now and redeem up to $250 instant credit1 toward the offers below or toward other eligible, must-have devices. | K33: Pre-order now and redeem up to $250 instant credit1 toward the offers below or toward other eligible, must-have devices. | L33: Pre-order now and redeem up to $250 instant credit1 toward the offers below or toward other eligible, must-have devices. | M33: Pre-order now and redeem up to $250 instant credit1 toward the offers below or toward other eligible, must-have devices. | N33: Pre-order now and redeem up to $250 instant credit1 toward the offers below or toward other eligible, must-have devices. | O33: Pre-order now and redeem up to $250 instant credit1 toward the offers below or toward other eligible, must-have devices. | P33: Pre-order now and redeem up to $250 instant credit1 toward the offers below or toward other eligible, must-have devices. | Q33: Pre-order now and redeem up to $250 instant credit1 toward the offers below or toward other eligible, must-have devices. | R33: Pre-order now and redeem up to $250 instant credit1 toward the offers below or toward other eligible, must-have devices. | S33: Pre-order now and redeem up to $250 instant credit1 toward the offers below or toward other eligible, must-have devices. | T33: Pre-order now and redeem up to $250 instant credit1 toward the offers below or toward other eligible, must-have devices. | U33: Pre-order now and redeem up to $250 instant credit1 toward the offers below or toward other eligible, must-have devices. | V33: Pre-order now and redeem up to $250 instant credit1 toward the offers below or toward other eligible, must-have devices. | W33: Pre-order now and redeem up to $250 instant credit1 toward the offers below or toward other eligible, must-have devices. | X33: Pre-order now and redeem up to $250 instant credit1 toward the offers below or toward other eligible, must-have devices. | Y33: Pre-order now and redeem up to $200 instant credit1 toward the offers below or toward other eligible, must-have devices.
B34: Table Line 2 | C34: Save $180 when you bundle Galaxy Buds Pro and Galaxy Watch3 with any Galaxy S21 5G purchase. | D34: Save $180 when you bundle Galaxy Buds Pro and Galaxy Watch3 with any Galaxy S21 5G purchase. | E34: Save $180 when you bundle Galaxy Buds Pro and Galaxy Watch3 with any Galaxy S21 5G purchase. | F34: Save $180 when you bundle Galaxy Buds Pro and Galaxy Watch3 with any Galaxy S21 5G purchase. | G34: Save $180 when you bundle Galaxy Buds Pro and Galaxy Watch3 with any Galaxy S21 5G purchase. | H34: Save $180 when you bundle Galaxy Buds Pro and Galaxy Watch3 with any Galaxy S21 5G purchase. | I34: Save $180 when you bundle Galaxy Buds Pro and Galaxy Watch3 with any Galaxy S21 5G purchase. | J34: Save $180 when you bundle Galaxy Buds Pro and Galaxy Watch3 with any Galaxy S21 5G purchase. | K34: Save $180 when you bundle Galaxy Buds Pro and Galaxy Watch3 with any Galaxy S21 5G purchase. | L34: Save $180 when you bundle Galaxy Buds Pro and Galaxy Watch3 with any Galaxy S21 5G purchase. | M34: Save $180 when you bundle Galaxy Buds Pro and Galaxy Watch3 with any Galaxy S21 5G purchase. | N34: Save $180 when you bundle Galaxy Buds Pro and Galaxy Watch3 with any Galaxy S21 5G purchase. | O34: Save $180 when you bundle Galaxy Buds Pro and Galaxy Watch3 with any Galaxy S21 5G purchase. | P34: Save $180 when you bundle Galaxy Buds Pro and Galaxy Watch3 with any Galaxy S21 5G purchase. | Q34: Save $180 when you bundle Galaxy Buds Pro and Galaxy Watch3 with any Galaxy S21 5G purchase. | R34: Save $180 when you bundle Galaxy Buds Pro and Galaxy Watch3 with any Galaxy S21 5G purchase. | S34: Save $180 when you bundle Galaxy Buds Pro and Galaxy Watch3 with any Galaxy S21 5G purchase. | T34: Save $180 when you bundle Galaxy Buds Pro and Galaxy Watch3 with any Galaxy S21 5G purchase. | U34: Save $180 when you bundle Galaxy Buds Pro and Galaxy Watch3 with any Galaxy S21 5G purchase. | V34: Save $180 when you bundle Galaxy Buds Pro and Galaxy Watch3 with any Galaxy S21 5G purchase. | W34: Save $180 when you bundle Galaxy Buds Pro and Galaxy Watch3 with any Galaxy S21 5G purchase. | X34: Save $180 when you bundle Galaxy Buds Pro and Galaxy Watch3 with any Galaxy S21 5G purchase. | Y34: Save $180 when you bundle Galaxy Buds Pro and Galaxy Watch3 with any Galaxy S21 5G purchase.
B35: Table Line 3 | C35: Get 15% off Galaxy Buds Pro, a 25W Travel Adapter and a UV Sanitizer when you bundle with any Galaxy S21 5G purchase. | D35: Get 15% off Galaxy Buds Pro, a 25W Travel Adapter and a UV Sanitizer when you bundle with any Galaxy S21 5G purchase. | E35: Get 15% off Galaxy Buds Pro, a 25W Travel Adapter and a UV Sanitizer when you bundle with any Galaxy S21 5G purchase. | F35: Get 15% off Galaxy Buds Pro, a 25W Travel Adapter and a UV Sanitizer when you bundle with any Galaxy S21 5G purchase. | G35: Get 15% off Galaxy Buds Pro, a 25W Travel Adapter and a UV Sanitizer when you bundle with any Galaxy S21 5G purchase. | H35: Get 15% off Galaxy Buds Pro, a 25W Travel Adapter and a UV Sanitizer when you bundle with any Galaxy S21 5G purchase. | I35: Get 15% off Galaxy Buds Pro, a 25W Travel Adapter and a UV Sanitizer when you bundle with any Galaxy S21 5G purchase. | J35: Get 15% off Galaxy Buds Pro, a 25W Travel Adapter and a UV Sanitizer when you bundle with any Galaxy S21 5G purchase. | K35: Get 15% off Galaxy Buds Pro, a 25W Travel Adapter and a UV Sanitizer when you bundle with any Galaxy S21 5G purchase. | L35: Get 15% off Galaxy Buds Pro, a 25W Travel Adapter and a UV Sanitizer when you bundle with any Galaxy S21 5G purchase. | M35: Get 15% off Galaxy Buds Pro, a 25W Travel Adapter and a UV Sanitizer when you bundle with any Galaxy S21 5G purchase. | N35: Get 15% off Galaxy Buds Pro, a 25W Travel Adapter and a UV Sanitizer when you bundle with any Galaxy S21 5G purchase. | O35: Get 15% off Galaxy Buds Pro, a 25W Travel Adapter and a UV Sanitizer when you bundle with any Galaxy S21 5G purchase. | P35: Get 15% off Galaxy Buds Pro, a 25W Travel Adapter and a UV Sanitizer when you bundle with any Galaxy S21 5G purchase. | Q35: Get 15% off Galaxy Buds Pro, a 25W Travel Adapter and a UV Sanitizer when you bundle with any Galaxy S21 5G purchase. | R35: Get 15% off Galaxy Buds Pro, a 25W Travel Adapter and a UV Sanitizer when you bundle with any Galaxy S21 5G purchase. | S35: Get 15% off Galaxy Buds Pro, a 25W Travel Adapter and a UV Sanitizer when you bundle with any Galaxy S21 5G purchase. | T35: Get 15% off Galaxy Buds Pro, a 25W Travel Adapter and a UV Sanitizer when you bundle with any Galaxy S21 5G purchase. | U35: Get 15% off Galaxy Buds Pro, a 25W Travel Adapter and a UV Sanitizer when you bundle with any Galaxy S21 5G purchase. | V35: Get 15% off Galaxy Buds Pro, a 25W Travel Adapter and a UV Sanitizer when you bundle with any Galaxy S21 5G purchase. | W35: Get 15% off Galaxy Buds Pro, a 25W Travel Adapter and a UV Sanitizer when you bundle with any Galaxy S21 5G purchase. | X35: Get 15% off Galaxy Buds Pro, a 25W Travel Adapter and a UV Sanitizer when you bundle with any Galaxy S21 5G purchase. | Y35: Get 15% off Galaxy Buds Pro, a 25W Travel Adapter and a UV Sanitizer when you bundle with any Galaxy S21 5G purchase.
B36: Table Line 4 | C36: Get $265 off Galaxy Tab S7 with any Galaxy S21 5G purchase. | D36: Get $265 off Galaxy Tab S7 with any Galaxy S21 5G purchase. | E36: Get $265 off Galaxy Tab S7 with any Galaxy S21 5G purchase. | F36: Get $265 off Galaxy Tab S7 with any Galaxy S21 5G purchase. | G36: Get $265 off Galaxy Tab S7 with any Galaxy S21 5G purchase. | H36: Get $265 off Galaxy Tab S7 with any Galaxy S21 5G purchase. | I36: Get $265 off Galaxy Tab S7 with any Galaxy S21 5G purchase. | J36: Get $265 off Galaxy Tab S7 with any Galaxy S21 5G purchase. | K36: Get $265 off Galaxy Tab S7 with any Galaxy S21 5G purchase. | L36: Get $265 off Galaxy Tab S7 with any Galaxy S21 5G purchase. | M36: Get $265 off Galaxy Tab S7 with any Galaxy S21 5G purchase. | N36: Get $265 off Galaxy Tab S7 with any Galaxy S21 5G purchase. | O36: Get $265 off Galaxy Tab S7 with any Galaxy S21 5G purchase. | P36: Get $265 off Galaxy Tab S7 with any Galaxy S21 5G purchase. | Q36: Get $265 off Galaxy Tab S7 with any Galaxy S21 5G purchase. | R36: Get $265 off Galaxy Tab S7 with any Galaxy S21 5G purchase. | S36: Get $265 off Galaxy Tab S7 with any Galaxy S21 5G purchase. | T36: Get $265 off Galaxy Tab S7 with any Galaxy S21 5G purchase. | U36: Get $265 off Galaxy Tab S7 with any Galaxy S21 5G purchase. | V36: Get $265 off Galaxy Tab S7 with any Galaxy S21 5G purchase. | W36: Get $265 off Galaxy Tab S7 with any Galaxy S21 5G purchase. | X36: Get $265 off Galaxy Tab S7 with any Galaxy S21 5G purchase. | Y36: Get $265 off Galaxy Tab S7 with any Galaxy S21 5G purchase.
B37: Table CTA 1 | C37: Pre-order now | D37: Pre-order now | E37: Pre-order now | F37: Pre-order now | G37: Pre-order now | H37: Pre-order now | I37: Pre-order now | J37: Pre-order now | K37: Pre-order now | L37: Pre-order now | M37: Pre-order now | N37: Pre-order now | O37: Pre-order now | P37: Pre-order now | Q37: Pre-order now | R37: Pre-order now | S37: Pre-order now | T37: Pre-order now | U37: Pre-order now | V37: Pre-order now | W37: Pre-order now | X37: Pre-order now | Y37: Pre-order now
A38: 4 | B38: Trade-in HL | C38: Trade up and save on your new Galaxyᶿ | D38: Trade up and save on your new Galaxyᶿ | E38: Trade up and save on your new Galaxyᶿ | F38: Trade up and save on your new Galaxyᶿ | G38: Trade up and save on your new Galaxyᶿ | H38: Trade up and save on your new Galaxyᶿ | I38: Trade up and save on your new Galaxyᶿ | J38: Trade up and save on your new Galaxyᶿ | K38: Trade up and save on your new Galaxyᶿ | L38: Trade up and save on your new Galaxyᶿ | M38: Trade up and save on your new Galaxyᶿ | N38: Trade up and save on your new Galaxyᶿ | O38: Trade up and save on your new Galaxyᶿ | P38: Trade up and save on your new Galaxyᶿ | Q38: Trade up and save on your new Galaxyᶿ | R38: Trade up and save on your new Galaxyᶿ | S38: Trade up and save on your new Galaxyᶿ | T38: Trade up and save on your new Galaxyᶿ | U38: Trade up and save on your new Galaxyᶿ | V38: Trade up and save on your new Galaxyᶿ | W38: Trade up and save on your new Galaxyᶿ | X38: Trade up and save on your new Galaxyᶿ | Y38: Trade up and save on your new Galaxyᶿ
B39: Trade-in SH | C39: Plus, get up to $250 instant credit.1 | D39: Plus, get up to $250 instant credit.1 | E39: Plus, get up to $250 instant credit.1 | F39: Plus, get up to $250 instant credit.1 | G39: Plus, get up to $250 instant credit.1 | H39: Plus, get up to $250 instant credit.1 | I39: Plus, get up to $250 instant credit.1 | J39: Plus, get up to $250 instant credit.1 | K39: Plus, get up to $250 instant credit.1 | L39: Plus, get up to $250 instant credit.1 | M39: Plus, get up to $250 instant credit.1 | N39: Plus, get up to $250 instant credit.1 | O39: Plus, get up to $250 instant credit.1 | P39: Plus, get up to $250 instant credit.1 | Q39: Plus, get up to $250 instant credit.1 | R39: Plus, get up to $250 instant credit.1 | S39: Plus, get up to $250 instant credit.1 | T39: Plus, get up to $250 instant credit.1 | U39: Plus, get up to $250 instant credit.1 | V39: Plus, get up to $250 instant credit.1 | W39: Plus, get up to $250 instant credit.1 | X39: Plus, get up to $250 instant credit.1 | Y39: Plus, get up to $200 instant credit.1
B40: Trade-in Table | C40: See "Trade-in Module" sheet for "Generic" version. | D40: See "Trade-in Module" sheet for "N-2 $550 TI" version. | E40: See "Trade-in Module" sheet for "N-3 $350 TI" version. | F40: See "Trade-in Module" sheet for "N-4 $250/$200 TI" version. | G40: S10+ Single Line Version | H40: S10 Single Line Version | I40: S9+ Single Line Version | J40: N10+ Single Line Version | K40: S20+ Single Line Version | L40: S20 Single Line Version | M40: See "Trade-in Module" sheet for "LO" version. | N40: See "Trade-in Module" sheet for "EPP Generic" version. | O40: See "Trade-in Module" sheet for "EPP N-2 $550 TI" version. | P40: See "Trade-in Module" sheet for "EPP N-3 $350 TI" version. | Q40: See "Trade-in Module" sheet for "EPP N-3 $350 TI" version. | R40: EPP S10+ Single Line Version | S40: EPP S10 Single Line Version | T40: EPP S9+ Single Line Version | U40: EPP N10+ Single Line Version | V40: EPP S20+ Single Line Version | W40: EPP S20 Single Line Version | X40: See "Trade-in Module" sheet for "EPP Generic" version. | Y40: See "Trade-in Module" sheet for "EPP LO" version.
B41: Trade-in CTA | C41: Pre-order now | D41: Pre-order now | E41: Pre-order now | F41: Pre-order now | G41: Pre-order now | H41: Pre-order now | I41: Pre-order now | J41: Pre-order now | K41: Pre-order now | L41: Pre-order now | M41: Pre-order now | N41: Pre-order now | O41: Pre-order now | P41: Pre-order now | Q41: Pre-order now | R41: Pre-order now | S41: Pre-order now | T41: Pre-order now | U41: Pre-order now | V41: Pre-order now | W41: Pre-order now | X41: Pre-order now | Y41: Pre-order now
B42: Trade-in Disclaimer | C42: Values reflect starting prices with maximum enhanced trade-in values applied. Trade-in values may vary if not all trade-in conditions are met. Not all eligible trade-in devices are listed. | D42: Values reflect starting prices with maximum enhanced trade-in values applied. Trade-in values may vary if not all trade-in conditions are met. Not all eligible trade-in devices are listed. | E42: Values reflect starting prices with maximum enhanced trade-in values applied. Trade-in values may vary if not all trade-in conditions are met. Not all eligible trade-in devices are listed. | F42: Values reflect starting prices with maximum enhanced trade-in values applied. Trade-in values may vary if not all trade-in conditions are met. Not all eligible trade-in devices are listed. | G42: Values reflect starting prices with maximum enhanced trade-in values applied. Trade-in values may vary if not all trade-in conditions are met. Not all eligible trade-in devices are listed. | H42: Values reflect starting prices with maximum enhanced trade-in values applied. Trade-in values may vary if not all trade-in conditions are met. Not all eligible trade-in devices are listed. | I42: Values reflect starting prices with maximum enhanced trade-in values applied. Trade-in values may vary if not all trade-in conditions are met. Not all eligible trade-in devices are listed. | J42: Values reflect starting prices with maximum enhanced trade-in values applied. Trade-in values may vary if not all trade-in conditions are met. Not all eligible trade-in devices are listed. | K42: Values reflect starting prices with maximum enhanced trade-in values applied. Trade-in values may vary if not all trade-in conditions are met. Not all eligible trade-in devices are listed. | L42: Values reflect starting prices with maximum enhanced trade-in values applied. Trade-in values may vary if not all trade-in conditions are met. Not all eligible trade-in devices are listed. | M42: Values reflect starting prices with maximum enhanced trade-in values applied. Trade-in values may vary if not all trade-in conditions are met. Not all eligible trade-in devices are listed. | N42: Values reflect starting prices with maximum enhanced trade-in values applied. Trade-in values may vary if not all trade-in conditions are met. Not all eligible trade-in devices are listed. | O42: Values reflect starting prices with maximum enhanced trade-in values applied. Trade-in values may vary if not all trade-in conditions are met. Not all eligible trade-in devices are listed. | P42: Values reflect starting prices with maximum enhanced trade-in values applied. Trade-in values may vary if not all trade-in conditions are met. Not all eligible trade-in devices are listed. | Q42: Values reflect starting prices with maximum enhanced trade-in values applied. Trade-in values may vary if not all trade-in conditions are met. Not all eligible trade-in devices are listed. | R42: Values reflect starting prices with maximum enhanced trade-in values applied. Trade-in values may vary if not all trade-in conditions are met. Not all eligible trade-in devices are listed. | S42: Values reflect starting prices with maximum enhanced trade-in values applied. Trade-in values may vary if not all trade-in conditions are met. Not all eligible trade-in devices are listed. | T42: Values reflect starting prices with maximum enhanced trade-in values applied. Trade-in values may vary if not all trade-in conditions are met. Not all eligible trade-in devices are listed. | U42: Values reflect starting prices with maximum enhanced trade-in values applied. Trade-in values may vary if not all trade-in conditions are met. Not all eligible trade-in devices are listed. | V42: Values reflect starting prices with maximum enhanced trade-in values applied. Trade-in values may vary if not all trade-in conditions are met. Not all eligible trade-in devices are listed. | W42: Values reflect starting prices with maximum enhanced trade-in values applied. Trade-in values may vary if not all trade-in conditions are met. Not all eligible trade-in devices are listed. | X42: Values reflect starting prices with maximum enhanced trade-in values applied. Trade-in values may vary if not all trade-in conditions are met. Not all eligible trade-in devices are listed. | Y42: Values reflect starting prices with maximum enhanced trade-in values applied. Trade-in values may vary if not all trade-in conditions are met. Not all eligible trade-in devices are listed.
...

Sheet Copy Deck Phase 3
A1: First | B1: Feature focused | C1: Lifestyle, Trade-in, Ecosystem, Compare | D1: Only feature Generic Compare chart AND trade-in chart across ALL versions
D2: Only versions 9-12 and 21-24. Only pricing in KV will change.
A3: Second | B3: Value focused | C3: Trade-in, Compare, Ecosystem, Lifestyle
A4: Third | B4: Instant Credit | C4: Ecosystem, Trade-in, Compare, Lifestyle
A5: Fourth | B5: Last minute | C5: KV 1, KV 2, Ecosystem, Trade-in, Compare | D5: For Phase 3, dropping Ecosystem and making the edits below.
A7: Changes from T2 noted in green text & yellow fields.
A9: # | B9: Component | C9: Generic/N-1 | D9: N-2 $550 | E9: N-3 $350 | F9: N-4 $250/200 | G9: S10+ | H9: S10 | I9: S9+ | J9: N10+ | K9: S20+ | L9: S20 | M9: LO | N9: EPP Generic/N-1 | O9: EPP N-2 $550 | P9: EPP N-3 $350 | Q9: EPP N-4 $250/200 | R9: EPP S10+ | S9: EPP S10 | T9: EPP S9+ | U9: EPP N10+ | V9: EPP S20+ | W9: EPP S20 | X9: EPP LO | Y9: EPP Non-Reservers | Z9: Notes
B10: SL 1 | C10: n/a | D10: n/a | E10: n/a | F10: n/a | G10: n/a | H10: n/a | I10: n/a | J10: n/a | K10: n/a | L10: n/a | M10: n/a | N10: n/a | O10: n/a | P10: n/a | Q10: n/a | R10: n/a | S10: n/a | T10: n/a | U10: n/a | V10: n/a | W10: n/a | X10: n/a | Y10: n/a
B11: PH 2 | C11: n/a | D11: n/a | E11: n/a | F11: n/a | G11: n/a | H11: n/a | I11: n/a | J11: n/a | K11: n/a | L11: n/a | M11: n/a | N11: n/a | O11: n/a | P11: n/a | Q11: n/a | R11: n/a | S11: n/a | T11: n/a | U11: n/a | V11: n/a | W11: n/a | X11: n/a | Y11: n/a
B12: EYEBROW | C12: <Samsung logo> | D12: <Samsung logo> | E12: <Samsung logo> | F12: <Samsung logo> | G12: <Samsung logo> | H12: <Samsung logo> | I12: <Samsung logo> | J12: <Samsung logo> | K12: <Samsung logo> | L12: <Samsung logo> | M12: <Samsung logo> | N12: <Samsung logo> | O12: <Samsung logo> | P12: <Samsung logo> | Q12: <Samsung logo> | R12: <Samsung logo> | S12: <Samsung logo> | T12: <Samsung logo> | U12: <Samsung logo> | V12: <Samsung logo> | W12: <Samsung logo> | X12: <Samsung logo> | Y12: <Samsung logo>
B13: HERO HL 1 | C13: NULL | D13: NULL | E13: NULL | F13: NULL | G13: NULL | H13: NULL | I13: NULL | J13: NULL | K13: NULL | L13: NULL | M13: NULL | N13: <EPP Banner audience list> | O13: <EPP Banner audience list> | P13: <EPP Banner audience list> | Q13: <EPP Banner audience list> | R13: <EPP Banner audience list> | S13: <EPP Banner audience list> | T13: <EPP Banner audience list> | U13: <EPP Banner audience list> | V13: <EPP Banner audience list> | W13: <EPP Banner audience list> | X13: <EPP Banner audience list> | Y13: <EPP Banner audience list>
A14: NO COUNTDOWN TIMER | B14: HERO SH 1 | C14: While pre-order has ended, the epic, new Galaxy S21 5G is available to buy now. | D14: While pre-order has ended, the epic, new Galaxy S21 5G is available to buy now. | E14: While pre-order has ended, the epic, new Galaxy S21 5G is available to buy now. | F14: While pre-order has ended, the epic, new Galaxy S21 5G is available to buy now. | G14: While pre-order has ended, the epic, new Galaxy S21 5G is available to buy now. | H14: While pre-order has ended, the epic, new Galaxy S21 5G is available to buy now. | I14: While pre-order has ended, the epic, new Galaxy S21 5G is available to buy now. | J14: While pre-order has ended, the epic, new Galaxy S21 5G is available to buy now. | K14: While pre-order has ended, the epic, new Galaxy S21 5G is available to buy now. | L14: While pre-order has ended, the epic, new Galaxy S21 5G is available to buy now. | M14: While pre-order has ended, the epic, new Galaxy S21 5G is available to buy now. | N14: Login to your Samsung Discount Program account to access your exclusive pricing below. | O14: Login to your Samsung Discount Program account to access your exclusive pricing below. | P14: Login to your Samsung Discount Program account to access your exclusive pricing below. | Q14: Login to your Samsung Discount Program account to access your exclusive pricing below. | R14: Login to your Samsung Discount Program account to access your exclusive pricing below. | S14: Login to your Samsung Discount Program account to access your exclusive pricing below. | T14: Login to your Samsung Discount Program account to access your exclusive pricing below. | U14: Login to your Samsung Discount Program account to access your exclusive pricing below. | V14: Login to your Samsung Discount Program account to access your exclusive pricing below. | W14: Login to your Samsung Discount Program account to access your exclusive pricing below. | X14: Login to your Samsung Discount Program account to access your exclusive pricing below. | Y14: Login to your Samsung Discount Program account to access your exclusive pricing below.
B15: HERO SC 1 | C15: NULL | D15: NULL | E15: NULL | F15: NULL | G15: NULL | H15: NULL | I15: NULL | J15: NULL | K15: NULL | L15: NULL | M15: NULL | N15: While pre-order has ended, the epic, new Galaxy S21 5G is available to buy now. | O15: While pre-order has ended, the epic, new Galaxy S21 5G is available to buy now. | P15: While pre-order has ended, the epic, new Galaxy S21 5G is available to buy now. | Q15: While pre-order has ended, the epic, new Galaxy S21 5G is available to buy now. | R15: While pre-order has ended, the epic, new Galaxy S21 5G is available to buy now. | S15: While pre-order has ended, the epic, new Galaxy S21 5G is available to buy now. | T15: While pre-order has ended, the epic, new Galaxy S21 5G is available to buy now. | U15: While pre-order has ended, the epic, new Galaxy S21 5G is available to buy now. | V15: While pre-order has ended, the epic, new Galaxy S21 5G is available to buy now. | W15: While pre-order has ended, the epic, new Galaxy S21 5G is available to buy now. | X15: While pre-order has ended, the epic, new Galaxy S21 5G is available to buy now. | Y15: While pre-order has ended, the epic, new Galaxy S21 5G is available to buy now.
A16: 1 | B16: KV 1 HL | C16: Galaxy S21 Ultra 5G | D16: Galaxy S21 Ultra 5G | E16: Galaxy S21 Ultra 5G | F16: Galaxy S21 Ultra 5G | G16: Galaxy S21 Ultra 5G | H16: Galaxy S21 Ultra 5G | I16: Galaxy S21 Ultra 5G | J16: Galaxy S21 Ultra 5G | K16: Galaxy S21 Ultra 5G | L16: Galaxy S21 Ultra 5G | M16: Galaxy S21 Ultra 5G | N16: Galaxy S21 Ultra 5G | O16: Galaxy S21 Ultra 5G | P16: Galaxy S21 Ultra 5G | Q16: Galaxy S21 Ultra 5G | R16: Galaxy S21 Ultra 5G | S16: Galaxy S21 Ultra 5G | T16: Galaxy S21 Ultra 5G | U16: Galaxy S21 Ultra 5G | V16: Galaxy S21 Ultra 5G | W16: Galaxy S21 Ultra 5G | X16: Galaxy S21 Ultra 5G | Y16: Galaxy S21 Ultra 5G
B17: KV 1 SH | C17: Welcome to the Everyday Epic | D17: Welcome to the Everyday Epic | E17: Welcome to the Everyday Epic | F17: Welcome to the Everyday Epic | G17: Welcome to the Everyday Epic | H17: Welcome to the Everyday Epic | I17: Welcome to the Everyday Epic | J17: Welcome to the Everyday Epic | K17: Welcome to the Everyday Epic | L17: Welcome to the Everyday Epic | M17: Welcome to the Everyday Epic | N17: Welcome to the Everyday Epic | O17: Welcome to the Everyday Epic | P17: Welcome to the Everyday Epic | Q17: Welcome to the Everyday Epic | R17: Welcome to the Everyday Epic | S17: Welcome to the Everyday Epic | T17: Welcome to the Everyday Epic | U17: Welcome to the Everyday Epic | V17: Welcome to the Everyday Epic | W17: Welcome to the Everyday Epic | X17: Welcome to the Everyday Epic | Y17: Welcome to the Everyday Epic
